Workbook
Name tab: '[1]tab 0D4'!$A$22:$H$27

Sheet PIB_Annuel (2016)
A1: REPUBLIQUE DU CAMEROUN
A2: Paix – Travail – Patrie
A3: ---------------
A4: INSTITUT NATIONAL DE LA STATISTIQUE
A7: Les Comptes Nationaux du Cameroun, troisième édition, selon le SCN 2008
A9: Optique production
A11: ="Tableau "&B11&": " -> Tableau 1: | B11: 1
A12: PIB courant, optique production
A13: Libellé | C13: =IF(ISNUMBER(B13),B13+1,1993) -> 1993 | D13: =IF(ISNUMBER(C13),C13+1,1993) -> 1994 | E13: =IF(ISNUMBER(D13),D13+1,1993) -> 1995 | F13: =IF(ISNUMBER(E13),E13+1,1993) -> 1996 | G13: =IF(ISNUMBER(F13),F13+1,1993) -> 1997 | H13: =IF(ISNUMBER(G13),G13+1,1993) -> 1998 | I13: =IF(ISNUMBER(H13),H13+1,1993) -> 1999 | J13: =IF(ISNUMBER(I13),I13+1,1993) -> 2000 | ... Y13: =IF(ISNUMBER(X13),X13+1,1993) -> 2015 | Z13: 2016 | AA13: 2017 | AB13: 2018 | AC13: 2019 | AD13: 2020 | AE13: 2021 | AF13: 2022 | AG13: 2023
A14: 1.Production | C14: 6451.0058 | D14: 7196.2655 | E14: 8053.9961 | F14: 8718.6443 | G14: 9411.0046 | H14: 10021.799 | I14: 10750.002 | J14: 11149.936 | K14: 12241.755 | L14: 12849.735 | M14: 13801.332 | N14: 14591.658 | O14: 15207.882 | P14: 16270.577 | Q14: 17203.184 | R14: 18985.061 | S14: 19575.51 | T14: 20668.467 | U14: 21794.216 | V14: 23299.339 | W14: 24785.014 | X14: 26524.661 | Y14: 27724.473 | Z14: 28744.934 | AA14: 29715.783 | AB14: 31667.666 | AC14: 33043.125 | AD14: 32915.833 | AE14: 35000.255 | AF14: 38576.808 | AG14: 41131.018
A15: 2.Consommation intermédiaire | C15: 2107.8862 | D15: 2523.2524 | E15: 2959.431 | F15: 3426.4008 | G15: 3574.0858 | H15: 3882.0357 | I15: 4192.6051 | J15: 4273.5991 | K15: 4922.1281 | L15: 4950.8597 | M15: 5299.8612 | N15: 5324.2508 | O15: 5655.3545 | P15: 6192.0018 | Q15: 6656.8954 | R15: 7464.5601 | S15: 7289.8447 | T15: 7908.9872 | U15: 8190.23 | V15: 8820.4878 | W15: 9162.1189 | X15: 9823.09 | Y15: 10231.279 | Z15: 10341.261 | AA15: 10574.777 | AB15: 11323.315 | AC15: 11738.906 | AD15: 11255.14 | AE15: 11938.478 | AF15: 12828.713 | AG15: 13328.025
A16: 3.Valeur Ajoutée(1-2) | C16: =+C14-C15 -> 4343.1196 | D16: =+D14-D15 -> 4673.0131 | E16: =+E14-E15 -> 5094.5651 | F16: =+F14-F15 -> 5292.2435 | G16: =+G14-G15 -> 5836.9189 | H16: =+H14-H15 -> 6139.7631 | I16: =+I14-I15 -> 6557.3969 | J16: =+J14-J15 -> 6876.3371 | ... Y16: =+Y14-Y15 -> 17493.194 | Z16: 18403.673 | AA16: 19141.006 | AB16: 20344.351 | AC16: 21304.219 | AD16: 21660.693 | AE16: 23061.777 | AF16: 25748.095 | AG16: 27802.993
A17: 4.Impôts sur les produits | C17: 238.96475 | D17: 269.66686 | E17: 328.56895 | F17: 382.68325 | G17: 460.55757 | H17: 525.59764 | I17: 561.06103 | J17: 628.13184 | K17: 702.68004 | L17: 715.13584 | M17: 759.67386 | N17: 660.372 | O17: 734.20484 | P17: 845.61215 | Q17: 906.57885 | R17: 840.45357 | S17: 851.0274 | T17: 851.07468 | U17: 830.78878 | V17: 917.00743 | W17: 1035.6585 | X17: 1264.5526 | Y17: 1549.8722 | Z17: 1634.893 | AA17: 1819.859 | AB17: 1858.978 | AC17: 1939.443 | AD17: 1807.814 | AE17: 1898.719 | AF17: 1913.925 | AG17: 2088.41
A18: PIB(3+4) | C18: =+C16+C17 -> 4582.0844 | D18: =+D16+D17 -> 4942.68 | E18: =+E16+E17 -> 5423.1341 | F18: =+F16+F17 -> 5674.9268 | G18: =+G16+G17 -> 6297.4764 | H18: =+H16+H17 -> 6665.3607 | I18: =+I16+I17 -> 7118.4579 | J18: =+J16+J17 -> 7504.4689 | ... Y18: =+Y16+Y17 -> 19043.067 | Z18: 20038.566 | AA18: 20960.865 | AB18: 22203.329 | AC18: 23243.662 | AD18: 23468.507 | AE18: 24960.496 | AF18: 27662.02 | AG18: 29891.403
A21: ="Tableau "&B21&": " -> Tableau 2: | B21: 2
A22: PIB aux prix de l'année précédente, optique production
A23: Libellé | C23: =IF(ISNUMBER(B23),B23+1,1993) -> 1993 | D23: =IF(ISNUMBER(C23),C23+1,1993) -> 1994 | E23: =IF(ISNUMBER(D23),D23+1,1993) -> 1995 | F23: =IF(ISNUMBER(E23),E23+1,1993) -> 1996 | G23: =IF(ISNUMBER(F23),F23+1,1993) -> 1997 | H23: =IF(ISNUMBER(G23),G23+1,1993) -> 1998 | I23: =IF(ISNUMBER(H23),H23+1,1993) -> 1999 | J23: =IF(ISNUMBER(I23),I23+1,1993) -> 2000 | ... Y23: =IF(ISNUMBER(X23),X23+1,1993) -> 2015 | Z23: 2016 | AA23: 2017 | AB23: 2018 | AC23: 2019 | AD23: 2020 | AE23: 2021 | AF23: 2022 | AG23: 2023
A24: 1.Production | D24: 6721.9212 | E24: 7550.3253 | F24: 8379.7953 | G24: 9363.6865 | H24: 9916.187 | I24: 10575.277 | J24: 11225.442 | K24: 11937.997 | L24: 12502.47 | M24: 13453.913 | N24: 14534.33 | O24: 14865.104 | P24: 15780.845 | Q24: 16962.232 | R24: 17938.633 | S24: 19367.8 | T24: 20329.016 | U24: 20995.399 | V24: 22737.896 | W24: 24391.358 | X24: 26191.539 | Y24: 27729.342 | Z24: 28730.147 | AA24: 29493.134 | AB24: 30770.424 | AC24: 33043.125 | AD24: 32656.279 | AE24: 33974.43 | AF24: 36023.615 | AG24: 39711.327
A25: 2.Consommation intermédiaire | D25: 2297.4008 | E25: 2769.7738 | F25: 3109.0922 | G25: 3894.8308 | H25: 3807.9544 | I25: 4190.3325 | J25: 4431.3181 | K25: 4761.6792 | L25: 4794.8968 | M25: 5138.8387 | N25: 5302.0691 | O25: 5427.4473 | P25: 5921.7411 | Q25: 6443.8404 | R25: 6960.6849 | S25: 7527.4384 | T25: 7677.7782 | U25: 7784.1612 | V25: 8576.5841 | W25: 9259.9149 | X25: 9822.78 | Y25: 10280.1 | Z25: 10499.395 | AA25: 10453.044 | AB25: 10807.988 | AC25: 11998.56 | AD25: 11203.557 | AE25: 11612.436 | AF25: 12113.462 | AG25: 13154.764
A26: 3.Valeur Ajoutée(1-2) | D26: =+D24-D25 -> 4424.5205 | E26: =+E24-E25 -> 4780.5515 | F26: =+F24-F25 -> 5270.7032 | G26: =+G24-G25 -> 5468.8557 | H26: =+H24-H25 -> 6108.2326 | I26: =+I24-I25 -> 6384.9448 | J26: =+J24-J25 -> 6794.1236 | K26: =+K24-K25 -> 7176.3181 | ... Y26: =+Y24-Y25 -> 17449.242 | Z26: 18230.751 | AA26: 19040.09 | AB26: 19962.436 | AC26: 21044.565 | AD26: 21452.722 | AE26: 22361.994 | AF26: 23910.153 | AG26: 26556.563
A27: 4.Impôts sur les produits | D27: 243.5609 | E27: 305.16968 | F27: 381.01991 | G27: 462.99284 | H27: 486.8333 | I27: 581.11063 | J27: 597.1434 | K27: 652.66362 | L27: 673.89504 | M27: 768.67291 | N27: 681.68871 | O27: 711.33962 | P27: 819.51058 | Q27: 878.55032 | R27: 801.05998 | S27: 839.41268 | T27: 866.29018 | U27: 859.24613 | V27: 941.21249 | W27: 1033.5193 | X27: 1242.6332 | Y27: 1535.0131 | Z27: 1676.0695 | AA27: 1708.077 | AB27: 1827.539 | AC27: 1930.338 | AD27: 1851.363 | AE27: 1890.093 | AF27: 1983.094 | AG27: 2003.943
A28: PIB(3+4) | D28: =+D26+D27 -> 4668.0814 | E28: =+E26+E27 -> 5085.7212 | F28: =+F26+F27 -> 5651.7231 | G28: =+G26+G27 -> 5931.8485 | H28: =+H26+H27 -> 6595.0659 | I28: =+I26+I27 -> 6966.0554 | J28: =+J26+J27 -> 7391.267 | K28: =+K26+K27 -> 7828.9817 | ... Y28: =+Y26+Y27 -> 18984.255 | Z28: 19906.821 | AA28: 20748.167 | AB28: 21789.975 | AC28: 22974.903 | AD28: 23304.085 | AE28: 24252.087 | AF28: 25893.247 | AG28: 28560.506
A31: ="Tableau "&C31&": " -> Tableau :
A32: PIB en volumes chaînés, optique production (base 100 = 2016)
A33: Libellé | C33: =C$13 -> 1993 | D33: =D$13 -> 1994 | E33: =E$13 -> 1995 | F33: =F$13 -> 1996 | G33: =G$13 -> 1997 | H33: =H$13 -> 1998 | I33: =I$13 -> 1999 | J33: =J$13 -> 2000 | ... Y33: =Y$13 -> 2015 | Z33: 2016 | AA33: 2017 | AB33: 2018 | AC33: 2019 | AD33: 2020 | AE33: 2021 | AF33: 2022 | AG33: 2023
A34: 1.Production | C34: 10869.691 | D34: 11326.173 | E34: 11883.426 | F34: 12364.133 | G34: 13278.884 | H34: 13991.694 | I34: 14764.42 | J34: 15417.405 | K34: 16507.084 | L34: 16858.638 | M34: 17651.309 | N34: 18588.782 | O34: 18937.135 | P34: 19650.598 | Q34: 20485.935 | R34: 21361.725 | S34: 21792.378 | T34: 22631.217 | U34: 22989.195 | V34: 23984.617 | W34: 25108.756 | X34: 26533.653 | Y34: 27738.743 | Z34: 28744.934 | AA34: 29493.134 | AB34: 30539.873 | AC34: 31866.347 | AD34: 31493.278 | AE34: 32506.125 | AF34: 33456.56 | AG34: 34440.496
A35: 2.Consommation intermédiaire | C35: 3437.7574 | D35: 3746.8373 | E35: 4112.9027 | F35: 4320.896 | G35: 4911.6142 | H35: 5233.0033 | I35: 5648.5889 | J35: 5970.2009 | K35: 6652.0468 | L35: 6480.0991 | M35: 6726.1418 | N35: 6728.9439 | O35: 6859.3666 | P35: 7182.4663 | Q35: 7474.5887 | R35: 7815.6939 | S35: 7881.53 | T35: 8300.9503 | U35: 8169.9381 | V35: 8555.3351 | W35: 8981.5525 | X35: 9629.1934 | Y35: 10077.183 | Z35: 10341.261 | AA35: 10453.044 | AB35: 10683.57 | AC35: 11320.665 | AD35: 10804.39 | AE35: 11147.377 | AF35: 11310.766 | AG35: 11598.237
A36: 3.Valeur Ajoutée(1-2) | C36: 7509.0622 | D36: 7649.8007 | E36: 7825.8428 | F36: 8096.4113 | G36: 8366.6038 | H36: 8755.5033 | I36: 9105.1404 | J36: 9433.8424 | K36: 9845.395 | L36: 10367.208 | M36: 10913.465 | N36: 11851.592 | O36: 12069.316 | P36: 12456.665 | Q36: 13000.257 | R36: 13532.358 | S36: 13908.077 | T36: 14321.927 | U36: 14829.004 | V36: 15436.516 | W36: 16132.273 | X36: 16902.456 | Y36: 17659.12 | Z36: 18403.673 | AA36: 19040.09 | AB36: 19857.189 | AC36: 20540.636 | AD36: 20683.816 | AE36: 21353.489 | AF36: 22139.022 | AG36: 22834.169
A37: 4.Impôts sur les produits | C37: 370.88372 | D37: 378.01713 | E37: 427.78473 | F37: 496.07396 | G37: 600.17963 | H37: 634.42107 | I37: 701.42786 | J37: 746.53734 | K37: 775.69346 | L37: 743.91751 | M37: 799.60925 | N37: 717.52449 | O37: 772.90314 | P37: 862.70516 | Q37: 896.30914 | R37: 791.98559 | S37: 791.00473 | T37: 805.19104 | U37: 812.92194 | V37: 920.9709 | W37: 1037.9864 | X37: 1245.4263 | Y37: 1511.7961 | Z37: 1634.893 | AA37: 1708.077 | AB37: 1715.2853 | AC37: 1781.1294 | AD37: 1700.2392 | AE37: 1777.6222 | AF37: 1856.6159 | AG37: 1943.9384
A38: PIB | C38: 7873.4899 | D38: 8021.2603 | E38: 8253.3956 | F38: 8601.2822 | G38: 8990.6893 | H38: 9415.5474 | I38: 9840.3114 | J38: 10217.433 | K38: 10659.262 | L38: 11136.48 | M38: 11743.769 | N38: 12571.571 | O38: 12851.7 | P38: 13341.296 | Q38: 13918.653 | R38: 14315.011 | S38: 14684.231 | T38: 15109.931 | U38: 15620.527 | V38: 16343.129 | W38: 17159.555 | X38: 18141.05 | Y38: 19169.095 | Z38: 20038.566 | AA38: 20748.167 | AB38: 21568.864 | AC38: 22318.39 | AD38: 22376.408 | AE38: 23123.524 | AF38: 23987.629 | AG38: 24766.768
A41: ="Tableau "&C41&": " -> Tableau :
A42: Tableau 3: Indice de volume du PIB (variation en pourcentage)
A43: Libellé | C43: =C$13 -> 1993 | D43: =D$13 -> 1994 | E43: =E$13 -> 1995 | F43: =F$13 -> 1996 | G43: =G$13 -> 1997 | H43: =H$13 -> 1998 | I43: =I$13 -> 1999 | J43: =J$13 -> 2000 | ... Y43: =Y$13 -> 2015 | Z43: 2016 | AA43: 2017 | AB43: 2018 | AC43: 2019 | AD43: 2020 | AE43: 2021 | AF43: 2022 | AG43: 2023
A44: 1.Production | C44: =IFERROR(100*(C34/B34-1),"") | D44: =IFERROR(100*(D34/C34-1),"") -> 4.1995839 | E44: =IFERROR(100*(E34/D34-1),"") -> 4.9200492 | F44: =IFERROR(100*(F34/E34-1),"") -> 4.0451868 | G44: =IFERROR(100*(G34/F34-1),"") -> 7.3984226 | H44: =IFERROR(100*(H34/G34-1),"") -> 5.3679956 | I44: =IFERROR(100*(I34/H34-1),"") -> 5.5227462 | J44: =IFERROR(100*(J34/I34-1),"") -> 4.4226944 | ... Y44: =IFERROR(100*(Y34/X34-1),"") -> 4.5417422 | Z44: 3.6273846 | AA44: 2.6028934 | AB44: 3.5490938 | AC44: 4.3434177 | AD44: -1.1707307 | AE44: 3.2160723 | AF44: 2.9238644 | AG44: 2.9409354
A45: 2.Consommation intermédiaire | C45: =IFERROR(100*(C35/B35-1),"") | D45: =IFERROR(100*(D35/C35-1),"") -> 8.9907398 | E45: =IFERROR(100*(E35/D35-1),"") -> 9.7699853 | F45: =IFERROR(100*(F35/E35-1),"") -> 5.0570918 | G45: =IFERROR(100*(G35/F35-1),"") -> 13.671197 | H45: =IFERROR(100*(H35/G35-1),"") -> 6.5434521 | I45: =IFERROR(100*(I35/H35-1),"") -> 7.9416272 | J45: =IFERROR(100*(J35/I35-1),"") -> 5.6936688 | ... Y45: =IFERROR(100*(Y35/X35-1),"") -> 4.6524103 | Z45: 2.6205542 | AA45: 1.0809417 | AB45: 2.2053515 | AC45: 5.9633155 | AD45: -4.5604676 | AE45: 3.174514 | AF45: 1.4657145 | AG45: 2.5415722
A46: 3.Valeur Ajoutée(1-2) | C46: =IFERROR(100*(C36/B36-1),"") | D46: =IFERROR(100*(D36/C36-1),"") -> 1.8742482 | E46: =IFERROR(100*(E36/D36-1),"") -> 2.301265 | F46: =IFERROR(100*(F36/E36-1),"") -> 3.4573716 | G46: =IFERROR(100*(G36/F36-1),"") -> 3.3371887 | H46: =IFERROR(100*(H36/G36-1),"") -> 4.6482352 | I46: =IFERROR(100*(I36/H36-1),"") -> 3.9933416 | J46: =IFERROR(100*(J36/I36-1),"") -> 3.610071 | ... Y46: =IFERROR(100*(Y36/X36-1),"") -> 4.4766524 | Z46: 4.2162514 | AA46: 3.4580977 | AB46: 4.2914672 | AC46: 3.4418105 | AD46: 0.69705911 | AE46: 3.2376665 | AF46: 3.6787104 | AG46: 3.1399138
A47: 4.Impôts sur les produits | C47: =IFERROR(100*(C37/B37-1),"") | D47: =IFERROR(100*(D37/C37-1),"") -> 1.9233558 | E47: =IFERROR(100*(E37/D37-1),"") -> 13.165434 | F47: =IFERROR(100*(F37/E37-1),"") -> 15.963458 | G47: =IFERROR(100*(G37/F37-1),"") -> 20.985917 | H47: =IFERROR(100*(H37/G37-1),"") -> 5.7051984 | I47: =IFERROR(100*(I37/H37-1),"") -> 10.561879 | J47: =IFERROR(100*(J37/I37-1),"") -> 6.431094 | ... Y47: =IFERROR(100*(Y37/X37-1),"") -> 21.387841 | Z47: 8.14243 | AA47: 4.4763786 | AB47: 0.42201072 | AC47: 3.8386683 | AD47: -4.5415101 | AE47: 4.5512979 | AF47: 4.4437855 | AG47: 4.7033191
A48: PIB | C48: =IFERROR(100*(C38/B38-1),"") | D48: =IFERROR(100*(D38/C38-1),"") -> 1.8768092 | E48: =IFERROR(100*(E38/D38-1),"") -> 2.8940014 | F48: =IFERROR(100*(F38/E38-1),"") -> 4.2150721 | G48: =IFERROR(100*(G38/F38-1),"") -> 4.5273138 | H48: =IFERROR(100*(H38/G38-1),"") -> 4.7255348 | I48: =IFERROR(100*(I38/H38-1),"") -> 4.5113042 | J48: =IFERROR(100*(J38/I38-1),"") -> 3.8324178 | ... Y48: =IFERROR(100*(Y38/X38-1),"") -> 5.666953 | Z48: 4.5357942 | AA48: 3.5411765 | AB48: 3.9555142 | AC48: 3.4750375 | AD48: 0.25995474 | AE48: 3.3388575 | AF48: 3.7369089 | AG48: 3.2480853
A51: ="Tableau "&C51&": " -> Tableau :
A52: Variation du déflateur du PIB (en pourcentage)
...

Sheet PIB_Trimestriel_Brut (2016)
A1: REPUBLIQUE DU CAMEROUN
A2: Paix – Travail – Patrie
A3: ---------------
A4: INSTITUT NATIONAL DE LA STATISTIQUE
A8: Offre du PIB trimestriel en volume chainé (reference 2016), Données brutes
A10: Libellé | B10: T1_1999 | C10: T2_1999 | D10: T3_1999 | E10: T4_1999 | F10: T1_2000 | G10: T2_2000 | H10: T3_2000 | I10: T4_2000 | J10: T1_2001 | K10: T2_2001 | L10: T3_2001 | M10: T4_2001 | N10: T1_2002 | O10: T2_2002 | P10: T3_2002 | Q10: T4_2002 | R10: T1_2003 | S10: T2_2003 | T10: T3_2003 | U10: T4_2003 | V10: T1_2004 | W10: T2_2004 | X10: T3_2004 | Y10: T4_2004 | Z10: T1_2005 | AA10: T2_2005 | AB10: T3_2005 | AC10: T4_2005 | AD10: T1_2006 | AE10: T2_2006 | AF10: T3_2006 | AG10: T4_2006 | AH10: T1_2007 | AI10: T2_2007 | AJ10: T3_2007 | AK10: T4_2007 | AL10: T1_2008 | AM10: T2_2008 | AN10: T3_2008 | AO10: T4_2008 | AP10: T1_2009 | AQ10: T2_2009 | AR10: T3_2009 | AS10: T4_2009 | AT10: T1_2010 | AU10: T2_2010 | AV10: T3_2010 | AW10: T4_2010 | AX10: T1_2011 | AY10: T2_2011 | AZ10: T3_2011 | BA10: T4_2011 | BB10: T1_2012 | BC10: T2_2012 | BD10: T3_2012 | BE10: T4_2012 | BF10: T1_2013 | BG10: T2_2013 | BH10: T3_2013 | BI10: T4_2013 | BJ10: T1_2014 | BK10: T2_2014 | BL10: T3_2014 | BM10: T4_2014 | BN10: T1_2015 | BO10: T2_2015 | BP10: T3_2015 | BQ10: T4_2015 | BR10: T1_2016 | BS10: T2_2016 | BT10: T3_2016 | BU10: T4_2016 | BV10: T1_2017 | BW10: T2_2017 | BX10: T3_2017 | BY10: T4_2017 | BZ10: T1_2018 | CA10: T2_2018 | CB10: T3_2018 | CC10: T4_2018 | CD10: T1_2019 | CE10: T2_2019 | CF10: T3_2019 | CG10: T4_2019 | CH10: T1_2020 | CI10: T2_2020 | CJ10: T3_2020 | CK10: T4_2020 | CL10: T1_2021 | CM10: T2_2021 | CN10: T3_2021 | CO10: T4_2021 | CP10: T1_2022 | CQ10: T2_2022 | CR10: T3_2022 | CS10: T4_2022 | CT10: T1_2023 | CU10: T2_2023 | CV10: T3_2023 | CW10: T4_2023 | CX10: T1_2024 | CY10: T2_2024 | CZ10: T3_2024 | DA10: T4_2024 | DD10: Croissance réelle 2024/2023 (en %) | DG10: 2023 | DH10: 2024
A11: Secteur primaire | B11: 475.82041 | C11: 553.79322 | D11: 510.6411 | E11: 487.17955 | F11: 477.18093 | G11: 568.69738 | H11: 523.76422 | I11: 493.96495 | J11: 504.06469 | K11: 575.63097 | L11: 544.90544 | M11: 508.82479 | N11: 484.61782 | O11: 573.40333 | P11: 561.15273 | Q11: 567.85595 | R11: 498.33092 | S11: 572.6477 | T11: 578.80902 | U11: 607.18923 | V11: 570.98413 | W11: 651.33722 | X11: 623.83928 | Y11: 598.56601 | Z11: 540.20482 | AA11: 587.90362 | AB11: 600.96905 | AC11: 594.42815 | AD11: 497.65008 | AE11: 592.07182 | AF11: 622.47632 | AG11: 611.5301 | AH11: 548.30036 | AI11: 634.34065 | AJ11: 634.26501 | AK11: 631.9867 | AL11: 588.30915 | AM11: 647.35308 | AN11: 626.81207 | AO11: 675.45808 | AP11: 596.31305 | AQ11: 660.22898 | AR11: 663.0404 | AS11: 683.33639 | AT11: 605.24741 | AU11: 696.20701 | AV11: 707.55743 | AW11: 724.55968 | AX11: 648.98311 | AY11: 724.32496 | AZ11: 722.0155 | BA11: 718.1314 | BB11: 668.95258 | BC11: 761.71968 | BD11: 755.72281 | BE11: 724.53789 | BF11: 720.05806 | BG11: 784.87105 | BH11: 780.23605 | BI11: 748.72931 | BJ11: 725.68264 | BK11: 825.64604 | BL11: 813.27024 | BM11: 827.93805 | BN11: 794.86586 | BO11: 872.91628 | BP11: 858.43961 | BQ11: 833.93357 | BR11: 770.15644 | BS11: 888.17341 | BT11: 877.98098 | BU11: 908.85217 | BV11: 853.93046 | BW11: 922.92598 | BX11: 906.52836 | BY11: 848.6072 | BZ11: 865.70766 | CA11: 961.89359 | CB11: 918.17194 | CC11: 921.98356 | CD11: 853.37212 | CE11: 1017.9222 | CF11: 978.57522 | CG11: 959.61503 | CH11: 898.38357 | CI11: 964.41985 | CJ11: 978.1266 | CK11: 1020.4365 | CL11: 952.19351 | CM11: 1012.1161 | CN11: 1002.7841 | CO11: 1006.6273 | CP11: 971.51953 | CQ11: 1089.7688 | CR11: 1040.6861 | CS11: 1006.577 | CT11: 947.09891 | CU11: 1111.3185 | CV11: 1087.1647 | CW11: 1052.3644 | CX11: 1026.5005 | CY11: 1105.0003 | CZ11: 1108.5796 | DA11: 1105.0668 | DD11: =(SUM(CX11:DA11)/SUM(CT11:CW11)-1)*100 -> 3.5064911 | DG11: =+SUM(CT11:CW11) -> 4197.9466 | DH11: =+SUM(CX11:DA11) -> 4345.1472
A12: Agrivriere | B12: 110.42004 | C12: 184.61926 | D12: 172.54472 | E12: 119.81086 | F12: 117.84399 | G12: 193.37086 | H12: 183.80127 | I12: 132.46288 | J12: 132.31098 | K12: 217.13538 | L12: 205.99642 | M12: 147.87917 | N12: 144.53971 | O12: 236.1626 | P12: 223.26108 | Q12: 159.8489 | R12: 140.69941 | S12: 230.82701 | T12: 220.31612 | U12: 160.13642 | V12: 161.51244 | W12: 266.86423 | X12: 253.92898 | Y12: 182.13512 | Z12: 161.2764 | AA12: 262.01955 | AB12: 246.40468 | AC12: 175.56013 | AD12: 152.64474 | AE12: 248.16638 | AF12: 233.71892 | AG12: 166.90093 | AH12: 156.49931 | AI12: 255.0802 | AJ12: 240.91368 | AK12: 172.56957 | AL12: 165.4053 | AM12: 269.86134 | AN12: 253.48437 | AO12: 179.4708 | AP12: 182.52677 | AQ12: 290.13229 | AR12: 263.22463 | AS12: 178.32121 | AT12: 179.53061 | AU12: 280.94339 | AV12: 259.5587 | AW12: 185.31097 | AX12: 171.12696 | AY12: 280.7823 | AZ12: 264.72008 | BA12: 187.74944 | BB12: 178.39649 | BC12: 287.54541 | BD12: 269.49269 | BE12: 192.20254 | BF12: 185.6571 | BG12: 303.09803 | BH12: 286.86702 | BI12: 205.99582 | BJ12: 192.59424 | BK12: 315.28044 | BL12: 298.50556 | BM12: 213.97084 | BN12: 200.53644 | BO12: 330.55883 | BP12: 317.56225 | BQ12: 233.19256 | BR12: 239.45078 | BS12: 390.87703 | BT12: 369.8281 | BU12: 265.4541 | BV12: 250.43865 | BW12: 409.7077 | BX12: 387.33212 | BY12: 277.00053 | BZ12: 259.97355 | CA12: 423.8132 | CB12: 400.49616 | CC12: 287.15237 | CD12: 272.28824 | CE12: 440.1251 | CF12: 410.35908 | CG12: 295.67182 | CH12: 225.41466 | CI12: 366.87892 | CJ12: 346.15308 | CK12: 247.77231 | CL12: 226.25134 | CM12: 370.27203 | CN12: 351.41994 | CO12: 253.15529 | CP12: 234.59036 | CQ12: 385.5012 | CR12: 366.4625 | CS12: 263.82321 | CT12: 241.64111 | CU12: 395.99302 | CV12: 374.70498 | CW12: 268.01034 | CX12: 250.57487 | CY12: 408.09195 | CZ12: 384.9164 | DA12: 275.20984 | DB12: =+SUM(CP12:CS12) -> 1250.3773 | DC12: =+SUM(CT12:CW12) -> 1280.3494 | DD12: =(SUM(CX12:DA12)/SUM(CT12:CW12)-1)*100 -> 3.0025877 | DG12: =+SUM(CT12:CW12) -> 1280.3494 | DH12: =+SUM(CX12:DA12) -> 1318.7931
A13: Agriexport | B13: 167.44766 | C13: 149.38359 | D13: 118.16583 | E13: 176.33729 | F13: 159.38347 | G13: 163.19571 | H13: 120.85687 | I13: 167.17574 | J13: 171.46529 | K13: 130.36752 | L13: 103.85338 | M13: 151.38096 | N13: 116.83648 | O13: 97.937655 | P13: 109.01749 | Q13: 214.36933 | R13: 145.49424 | S13: 113.47279 | T13: 133.98853 | U13: 237.60273 | V13: 175.98075 | W13: 123.0849 | X13: 100.73374 | Y13: 185.13216 | Z13: 147.58027 | AA13: 95.842998 | AB13: 127.47722 | AC13: 195.21933 | AD13: 102.59043 | AE13: 100.40582 | AF13: 155.9165 | AG13: 220.53996 | AH13: 136.38686 | AI13: 121.61009 | AJ13: 134.19765 | AK13: 210.97403 | AL13: 158.78335 | AM13: 102.43996 | AN13: 93.18782 | AO13: 233.04924 | AP13: 140.74864 | AQ13: 99.255932 | AR13: 126.96547 | AS13: 236.17714 | AT13: 138.94209 | AU13: 126.42555 | AV13: 160.40063 | AW13: 260.76656 | AX13: 193.91159 | AY13: 135.63384 | AZ13: 152.86422 | BA13: 247.95114 | BB13: 189.13017 | BC13: 152.33531 | BD13: 171.27949 | BE13: 245.53556 | BF13: 235.74037 | BG13: 147.97975 | BH13: 160.71972 | BI13: 241.73143 | BJ13: 208.29016 | BK13: 165.29294 | BL13: 155.62371 | BM13: 285.1627 | BN13: 250.00171 | BO13: 168.70266 | BP13: 187.48171 | BQ13: 274.3319 | BR13: 180.52943 | BS13: 119.60395 | BT13: 126.47714 | BU13: 293.02048 | BV13: 232.08355 | BW13: 136.98062 | BX13: 135.00411 | BY13: 181.59072 | BZ13: 217.13087 | CA13: 122.20399 | CB13: 113.72021 | CC13: 249.67581 | CD13: 188.51451 | CE13: 149.54352 | CF13: 140.26352 | CG13: 245.51427 | CH13: 279.36118 | CI13: 148.84728 | CJ13: 207.84355 | CK13: 397.28976 | CL13: 344.32053 | CM13: 201.2993 | CN13: 203.52694 | CO13: 353.86013 | CP13: 337.82909 | CQ13: 226.21105 | CR13: 202.59873 | CS13: 323.25321 | CT13: 298.60579 | CU13: 230.73935 | CV13: 198.06519 | CW13: 344.32471 | CX13: 370.64363 | CY13: 191.56177 | CZ13: 213.9705 | DA13: 397.68256 | DB13: =+SUM(CP13:CS13) -> 1089.8921 | DC13: =+SUM(CT13:CW13) -> 1071.735 | DD13: =(SUM(CX13:DA13)/SUM(CT13:CW13)-1)*100 -> 9.5287925 | DE13: =+DE15+DE16 -> 2583.831 | DG13: =+SUM(CT13:CW13) -> 1071.735 | DH13: =+SUM(CX13:DA13) -> 1173.8585
A14: Elev_Chass_Pech | B14: 89.09799 | C14: 89.165908 | D14: 89.302917 | E14: 89.511392 | F14: 90.147958 | G14: 90.681986 | H14: 91.267866 | I14: 91.887332 | J14: 92.601869 | K14: 93.928876 | L14: 95.942874 | M14: 98.68076 | N14: 102.09994 | O14: 104.69001 | P14: 106.38 | Q14: 107.14923 | R14: 106.9813 | S14: 107.33638 | T14: 108.19389 | U14: 109.59676 | V14: 111.65219 | W14: 112.98277 | X14: 113.5008 | Y14: 113.17265 | Z14: 112.07397 | AA14: 111.5818 | AB14: 111.65445 | AC14: 112.2734 | AD14: 113.36634 | AE14: 114.32385 | AF14: 115.10121 | AG14: 115.69952 | AH14: 116.10338 | AI14: 116.93106 | AJ14: 118.14848 | AK14: 119.7339 | AL14: 121.67159 | AM14: 123.79151 | AN14: 126.14082 | AO14: 128.76171 | AP14: 131.75831 | AQ14: 134.16572 | AR14: 135.9707 | AS14: 137.13865 | AT14: 137.60403 | AU14: 138.66468 | AV14: 140.34397 | AW14: 142.6664 | AX14: 145.70762 | AY14: 148.24119 | AZ14: 150.25156 | BA14: 151.70955 | BB14: 152.59464 | BC14: 153.51836 | BD14: 154.49777 | BE14: 155.54687 | BF14: 156.64652 | BG14: 157.97576 | BH14: 159.51055 | BI14: 161.24586 | BJ14: 163.25107 | BK14: 164.70699 | BL14: 165.64199 | BM14: 166.04997 | BN14: 165.90553 | BO14: 166.59973 | BP14: 168.15567 | BQ14: 170.62992 | BR14: 174.04408 | BS14: 177.11974 | BT14: 179.77017 | BU14: 181.92601 | BV14: 183.48485 | BW14: 185.07138 | BX14: 186.64601 | BY14: 188.22075 | BZ14: 189.80707 | CA14: 191.393 | CB14: 192.98165 | CC14: 194.57626 | CD14: 196.1801 | CE14: 197.62152 | CF14: 198.89876 | CG14: 200.01077 | CH14: 200.86539 | CI14: 201.75692 | CJ14: 202.64422 | CK14: 203.52678 | CL14: 204.40281 | CM14: 205.81603 | CN14: 207.76397 | CO14: 210.24731 | CP14: 213.26738 | CQ14: 215.87442 | CR14: 218.06873 | CS14: 219.85084 | CT14: 221.21484 | CU14: 222.85729 | CV14: 224.77558 | CW14: 226.96843 | CX14: 229.43518 | CY14: 231.28411 | CZ14: 232.51654 | DA14: 233.13266 | DD14: =(SUM(CX14:DA14)/SUM(CT14:CW14)-1)*100 -> 3.4105599 | DG14: =+SUM(CT14:CW14) -> 895.81614 | DH14: =+SUM(CX14:DA14) -> 926.36849
A15: Sylviculture | B15: 146.02944 | C15: 152.11038 | D15: 142.55347 | E15: 138.30258 | F15: 142.3628 | G15: 143.67811 | H15: 137.23317 | I15: 132.70355 | J15: 140.69499 | K15: 141.65963 | L15: 138.23896 | M15: 131.89438 | N15: 130.7348 | O15: 129.99021 | P15: 120.41577 | Q15: 117.6663 | R15: 116.59086 | S15: 122.98946 | T15: 122.8691 | U15: 131.18987 | V15: 139.43447 | W15: 146.43345 | X15: 146.64698 | Y15: 137.9067 | Z15: 124.13357 | AA15: 119.9146 | AB15: 121.59242 | AC15: 125.43745 | AD15: 125.26915 | AE15: 127.20732 | AF15: 127.20216 | AG15: 129.78742 | AH15: 141.39163 | AI15: 144.60542 | AJ15: 146.15266 | AK15: 143.98534 | AL15: 146.19798 | AM15: 152.91362 | AN15: 152.33235 | AO15: 149.49236 | AP15: 140.69057 | AQ15: 141.64472 | AR15: 142.19329 | AS15: 142.14383 | AT15: 150.37108 | AU15: 153.23665 | AV15: 153.50155 | AW15: 151.49804 | AX15: 150.65431 | AY15: 156.29304 | AZ15: 154.59014 | BA15: 152.28315 | BB15: 160.5522 | BC15: 163.3391 | BD15: 161.48214 | BE15: 156.45185 | BF15: 167.2679 | BG15: 164.79433 | BH15: 167.01648 | BI15: 164.49801 | BJ15: 176.75341 | BK15: 172.85184 | BL15: 184.19496 | BM15: 195.82753 | BN15: 199.31595 | BO15: 200.95924 | BP15: 184.97699 | BQ15: 180.63114 | BR15: 180.54972 | BS15: 186.17031 | BT15: 189.52282 | BU15: 190.81915 | BV15: 187.92341 | BW15: 191.16628 | BX15: 197.54612 | BY15: 201.79519 | BZ15: 206.35184 | CA15: 215.20029 | CB15: 201.64086 | CC15: 200.71478 | CD15: 200.84008 | CE15: 223.02412 | CF15: 221.98513 | CG15: 228.30063 | CH15: 216.93567 | CI15: 225.05174 | CJ15: 214.3124 | CK15: 216.79918 | CL15: 219.07753 | CM15: 218.94704 | CN15: 228.17696 | CO15: 228.88887 | CP15: 226.98956 | CQ15: 247.44891 | CR15: 235.84825 | CS15: 231.60022 | CT15: 222.90507 | CU15: 235.62796 | CV15: 258.29521 | CW15: 259.69779 | CX15: 228.77605 | CY15: 235.34208 | CZ15: 251.97139 | DA15: 254.69591 | DC15: =+DC12/DB12-1 -> 0.023970507 | DD15: =(SUM(CX15:DA15)/SUM(CT15:CW15)-1)*100 -> -0.5878592 | DE15: =+DB61*(1+DC15) -> 1799.023 | DG15: =+SUM(CT15:CW15) -> 976.52603 | DH15: =+SUM(CX15:DA15) -> 970.78543
A16: Secteur secondaire | B16: 804.51373 | C16: 828.43201 | D16: 768.84344 | E16: 787.62202 | F16: 814.68717 | G16: 827.32406 | H16: 808.25396 | I16: 805.3371 | J16: 830.65798 | K16: 846.37235 | L16: 801.19667 | M16: 838.34797 | N16: 944.67192 | O16: 925.09469 | P16: 945.79971 | Q16: 924.49414 | R16: 938.15393 | S16: 946.89369 | T16: 942.2018 | U16: 947.2727 | V16: 997.35587 | W16: 1032.5701 | X16: 1015.0908 | Y16: 999.70918 | Z16: 1015.5646 | AA16: 985.03731 | AB16: 977.04615 | AC16: 951.66561 | AD16: 1020.9247 | AE16: 1008.2866 | AF16: 991.5699 | AG16: 1092.7291 | AH16: 1055.2564 | AI16: 1000.318 | AJ16: 1014.1175 | AK16: 976.0148 | AL16: 1042.053 | AM16: 1054.5594 | AN16: 994.90345 | AO16: 946.94153 | AP16: 1024.7376 | AQ16: 1002.2558 | AR16: 992.6389 | AS16: 985.85586 | AT16: 1027.0829 | AU16: 993.97063 | AV16: 969.4421 | AW16: 953.58995 | AX16: 1004.8738 | AY16: 937.09729 | AZ16: 967.35065 | BA16: 975.34651 | BB16: 1075.4859 | BC16: 1054.8575 | BD16: 1034.0396 | BE16: 976.57183 | BF16: 1123.0012 | BG16: 1037.2164 | BH16: 1061.5498 | BI16: 1047.5175 | BJ16: 1078.9604 | BK16: 1055.4436 | BL16: 1074.8062 | BM16: 1129.4739 | BN16: 1114.0078 | BO16: 1120.5115 | BP16: 1163.0517 | BQ16: 1219.4879 | BR16: 1228.3376 | BS16: 1235.8674 | BT16: 1190.4939 | BU16: 1191.0561 | BV16: 1231.9179 | BW16: 1248.2788 | BX16: 1238.0332 | BY16: 1195.8561 | BZ16: 1281.2894 | CA16: 1306.541 | CB16: 1239.4199 | CC16: 1230.9429 | CD16: 1322.5325 | CE16: 1325.7503 | CF16: 1296.0082 | CG16: 1304.1583 | CH16: 1344.7198 | CI16: 1362.6752 | CJ16: 1335.6705 | CK16: 1353.8901 | CL16: 1393.9321 | CM16: 1451.0386 | CN16: 1383.0074 | CO16: 1383.6822 | CP16: 1443.6984 | CQ16: 1494.7214 | CR16: 1421.1146 | CS16: 1439.7136 | CT16: 1497.1089 | CU16: 1512.2798 | CV16: 1449.4107 | CW16: 1473.1901 | CX16: 1513.287 | CY16: 1543.7871 | CZ16: 1472.3528 | DA16: 1470.8741 | DC16: =+DC13/DB13-1 -> -0.016659483 | DD16: =(SUM(CX16:DA16)/SUM(CT16:CW16)-1)*100 -> 1.1515773 | DE16: =+DB62*(1+DC16) -> 784.808 | DG16: =+SUM(CT16:CW16) -> 5931.9896 | DH16: =+SUM(CX16:DA16) -> 6000.301
A17: Industries Extractives | B17: 2743.1515 | C17: 2667.6171 | D17: 2377.5173 | E17: 1978.0159 | F17: 1994.964 | G17: 1939.9469 | H17: 1941.3797 | I17: 1989.9126 | J17: 1588.6165 | K17: 1582.3655 | L17: 1455.2461 | M17: 1314.733 | N17: 1624.2956 | O17: 1440.3761 | P17: 1360.7256 | Q17: 1183.734 | R17: 1116.7383 | S17: 1101.4563 | T17: 1115.0165 | U17: 1135.3962 | V17: 1097.6211 | W17: 1103.1582 | X17: 1116.9627 | Y17: 969.54259 | Z17: 815.52131 | AA17: 723.45603 | AB17: 685.63444 | AC17: 669.09897 | AD17: 750.87735 | AE17: 730.66519 | AF17: 664.34984 | AG17: 587.39683 | AH17: 546.68028 | AI17: 498.0478 | AJ17: 506.81187 | AK17: 510.39131 | AL17: 572.99837 | AM17: 596.20085 | AN17: 575.851 | AO17: 525.27233 | AP17: 531.22898 | AQ17: 483.7944 | AR17: 489.25916 | AS17: 461.86924 | AT17: 444.33067 | AU17: 410.64062 | AV17: 355.56091 | AW17: 285.62727 | AX17: 202.38028 | AY17: 165.81204 | AZ17: 147.71368 | BA17: 125.76189 | BB17: 192.98547 | BC17: 180.37325 | BD17: 170.18188 | BE17: 149.63794 | BF17: 165.31448 | BG17: 159.24647 | BH17: 177.24766 | BI17: 168.88297 | BJ17: 163.2625 | BK17: 155.43568 | BL17: 154.22037 | BM17: 151.31328 | BN17: 156.36865 | BO17: 180.78545 | BP17: 187.42901 | BQ17: 195.82281 | BR17: 192.2554 | BS17: 183.98304 | BT17: 164.87888 | BU17: 157.61768 | BV17: 152.0608 | BW17: 150.48618 | BX17: 139.3641 | BY17: 134.45392 | BZ17: 130.68082 | CA17: 139.77521 | CB17: 145.38115 | CC17: 144.53721 | CD17: 144.36716 | CE17: 145.76079 | CF17: 154.99095 | CG17: 161.03934 | CH17: 156.46239 | CI17: 154.79342 | CJ17: 153.35589 | CK17: 156.88887 | CL17: 150.53295 | CM17: 155.41431 | CN17: 149.17215 | CO17: 147.7804 | CP17: 147.46865 | CQ17: 150.93329 | CR17: 141.99913 | CS17: 154.46286 | CT17: 150.20101 | CU17: 145.78633 | CV17: 140.07616 | CW17: 147.51879 | CX17: 143.78111 | CY17: 136.50762 | CZ17: 132.72891 | DA17: 121.07562 | DD17: =(SUM(CX17:DA17)/SUM(CT17:CW17)-1)*100 -> -8.4802157 | DG17: =+SUM(CT17:CW17) -> 583.58229 | DH17: =+SUM(CX17:DA17) -> 534.09326
A18: dont extraction d'hydrocarbure | B18: 4432.263 | C18: 4270.9804 | D18: 3820.3721 | E18: 3049.6347 | F18: 3097.5017 | G18: 2941.9641 | H18: 2957.2466 | I18: 3122.748 | J18: 2388.2108 | K18: 2363.8247 | L18: 2207.216 | M18: 1965.5127 | N18: 2434.7117 | O18: 2144.6654 | P18: 2006.2793 | Q18: 1753.1156 | R18: 1607.0338 | S18: 1564.314 | T18: 1581.2096 | U18: 1699.6456 | V18: 1584.7321 | W18: 1544.1048 | X18: 1609.309 | Y18: 1378.5052 | Z18: 1060.2568 | AA18: 891.14208 | AB18: 835.13525 | AC18: 836.67645 | AD18: 932.71266 | AE18: 910.58754 | AF18: 829.49654 | AG18: 729.42691 | AH18: 647.48813 | AI18: 592.31409 | AJ18: 605.13638 | AK18: 621.21195 | AL18: 702.6529 | AM18: 710.6329 | AN18: 690.97848 | AO18: 640.63798 | AP18: 636.28939 | AQ18: 575.06961 | AR18: 581.01301 | AS18: 548.13623 | AT18: 519.57941 | AU18: 473.28154 | AV18: 403.86244 | AW18: 319.79812 | AX18: 198.80422 | AY18: 166.78639 | AZ18: 134.71491 | BA18: 111.48872 | BB18: 187.20304 | BC18: 170.439 | BD18: 161.2826 | BE18: 146.69461 | BF18: 150.08266 | BG18: 152.68841 | BH18: 169.06431 | BI18: 167.27883 | BJ18: 156.9928 | BK18: 148.2293 | BL18: 145.28483 | BM18: 139.86572 | BN18: 149.06995 | BO18: 175.12829 | BP18: 177.11233 | BQ18: 180.62827 | BR18: 181.65093 | BS18: 168.4621 | BT18: 154.17825 | BU18: 148.12872 | BV18: 140.45923 | BW18: 137.50742 | BX18: 125.30712 | BY18: 123.90923 | BZ18: 118.60959 | CA18: 126.82047 | CB18: 133.21569 | CC18: 132.75508 | CD18: 131.88238 | CE18: 133.06078 | CF18: 141.73697 | CG18: 147.46657 | CH18: 143.98427 | CI18: 141.84758 | CJ18: 140.50827 | CK18: 144.52994 | CL18: 138.28895 | CM18: 143.44413 | CN18: 139.52993 | CO18: 137.96038 | CP18: 137.13739 | CQ18: 139.23376 | CR18: 131.21751 | CS18: 142.91097 | CT18: 138.88881 | CU18: 134.37093 | CV18: 129.36562 | CW18: 136.14448 | CX18: 132.52316 | CY18: 124.82682 | CZ18: 121.87127 | DA18: 109.95153 | DD18: =(SUM(CX18:DA18)/SUM(CT18:CW18)-1)*100 -> -9.2056122 | DG18: =+SUM(CT18:CW18) -> 538.76984 | DH18: =+SUM(CX18:DA18) -> 489.17278
A19: Industrie Agro-alimentaire | B19: 154.19638 | C19: 170.30919 | D19: 157.24357 | E19: 167.98252 | F19: 171.475 | G19: 165.72274 | H19: 161.8481 | I19: 162.80037 | J19: 164.68861 | K19: 176.65672 | L19: 162.77044 | M19: 169.79882 | N19: 191.07321 | O19: 191.45519 | P19: 193.74367 | Q19: 205.53557 | R19: 215.81454 | S19: 216.55807 | T19: 204.03852 | U19: 215.21767 | V19: 219.61304 | W19: 214.80837 | X19: 213.14908 | Y19: 213.71308 | Z19: 222.36308 | AA19: 207.46301 | AB19: 206.1745 | AC19: 203.99244 | AD19: 210.60113 | AE19: 210.40477 | AF19: 202.38897 | AG19: 223.78584 | AH19: 243.34361 | AI19: 224.83308 | AJ19: 212.62844 | AK19: 228.87637 | AL19: 250.81227 | AM19: 259.62074 | AN19: 228.68647 | AO19: 240.24158 | AP19: 257.97885 | AQ19: 261.85557 | AR19: 246.74912 | AS19: 259.04733 | AT19: 271.48943 | AU19: 250.87285 | AV19: 247.81239 | AW19: 263.2592 | AX19: 286.54203 | AY19: 280.61668 | AZ19: 266.93832 | BA19: 282.03619 | BB19: 299.79465 | BC19: 284.9252 | BD19: 297.26986 | BE19: 313.38497 | BF19: 320.37707 | BG19: 312.56273 | BH19: 298.08553 | BI19: 326.81324 | BJ19: 319.59694 | BK19: 313.64448 | BL19: 302.3535 | BM19: 321.25776 | BN19: 328.64269 | BO19: 314.96401 | BP19: 307.55588 | BQ19: 330.26649 | BR19: 342.07276 | BS19: 329.8275 | BT19: 325.99978 | BU19: 347.52496 | BV19: 370.34042 | BW19: 358.18407 | BX19: 330.44493 | BY19: 345.39758 | BZ19: 360.90738 | CA19: 374.85478 | CB19: 356.55797 | CC19: 339.39136 | CD19: 376.21759 | CE19: 379.05159 | CF19: 355.71781 | CG19: 354.5028 | CH19: 386.28602 | CI19: 392.73901 | CJ19: 366.40018 | CK19: 373.92097 | CL19: 412.54967 | CM19: 436.27903 | CN19: 410.45746 | CO19: 404.89469 | CP19: 435.98441 | CQ19: 449.34704 | CR19: 420.88382 | CS19: 426.97861 | CT19: 454.48102 | CU19: 467.45608 | CV19: 437.68037 | CW19: 441.45614 | CX19: 462.99987 | CY19: 482.40651 | CZ19: 453.67101 | DA19: 452.53369 | DD19: =(SUM(CX19:DA19)/SUM(CT19:CW19)-1)*100 -> 2.805964 | DE19: =+SUM(CX19:DA20)/SUM(CT19:CW20)-1 -> 0.023000093 | DG19: =+SUM(CT19:CW19) -> 1801.0736 | DH19: =+SUM(CX19:DA19) -> 1851.6111
A20: Autres Industries Manufacturières | B20: 107.32315 | C20: 105.50996 | D20: 102.51422 | E20: 106.36947 | F20: 114.27596 | G20: 119.70878 | H20: 115.77627 | I20: 124.01249 | J20: 147.37331 | K20: 143.43062 | L20: 146.7642 | M20: 163.38236 | N20: 172.0022 | O20: 165.5337 | P20: 172.7734 | Q20: 170.91555 | R20: 175.32242 | S20: 175.09502 | T20: 177.2091 | U20: 194.65737 | V20: 196.66512 | W20: 191.42283 | X20: 204.942 | Y20: 218.15501 | Z20: 211.77921 | AA20: 210.29439 | AB20: 217.15147 | AC20: 214.7676 | AD20: 224.46967 | AE20: 219.18176 | AF20: 229.98349 | AG20: 299.08328 | AH20: 259.90123 | AI20: 249.61709 | AJ20: 269.14572 | AK20: 241.63182 | AL20: 250.36781 | AM20: 216.61347 | AN20: 222.52725 | AO20: 212.7574 | AP20: 242.50852 | AQ20: 235.2302 | AR20: 238.48895 | AS20: 239.45726 | AT20: 239.70914 | AU20: 243.41319 | AV20: 246.64222 | AW20: 250.22488 | AX20: 274.40411 | AY20: 263.70897 | AZ20: 284.57722 | BA20: 293.04376 | BB20: 319.58699 | BC20: 307.41801 | BD20: 287.95896 | BE20: 276.32778 | BF20: 313.97681 | BG20: 300.72327 | BH20: 298.5991 | BI20: 311.19022 | BJ20: 315.82471 | BK20: 302.92925 | BL20: 323.04682 | BM20: 343.64236 | BN20: 348.03171 | BO20: 343.17111 | BP20: 345.70404 | BQ20: 332.30715 | BR20: 358.19336 | BS20: 352.62604 | BT20: 364.18214 | BU20: 353.21846 | BV20: 352.86933 | BW20: 360.14224 | BX20: 373.27361 | BY20: 368.05882 | BZ20: 407.72527 | CA20: 397.0024 | CB20: 356.03079 | CC20: 367.74205 | CD20: 401.22641 | CE20: 393.99508 | CF20: 368.51995 | CG20: 365.71692 | CH20: 381.55 | CI20: 376.98199 | CJ20: 363.48008 | CK20: 364.86518 | CL20: 392.43423 | CM20: 386.29278 | CN20: 380.44238 | CO20: 374.63188 | CP20: 414.6794 | CQ20: 404.62256 | CR20: 400.72527 | CS20: 382.0152 | CT20: 420.42598 | CU20: 409.77332 | CV20: 414.73306 | CW20: 397.65172 | CX20: 428.62313 | CY20: 422.50272 | CZ20: 418.41413 | DA20: 401.71106 | DD20: =(SUM(CX20:DA20)/SUM(CT20:CW20)-1)*100 -> 1.745236 | DG20: =+SUM(CT20:CW20) -> 1642.5841 | DH20: =+SUM(CX20:DA20) -> 1671.251
A21: Electricité | B21: 19.745033 | C21: 20.084178 | D21: 19.610171 | E21: 20.924513 | F21: 21.718435 | G21: 21.288268 | H21: 21.049194 | I21: 21.297573 | J21: 21.0939 | K21: 20.184598 | L21: 21.202476 | M21: 21.795434 | N21: 18.62577 | O21: 20.396511 | P21: 24.45993 | Q21: 25.780877 | R21: 23.401825 | S21: 21.730622 | T21: 22.359802 | U21: 27.130435 | V21: 26.202391 | W21: 24.232203 | X21: 26.907075 | Y21: 28.673299 | Z21: 25.933368 | AA21: 27.695842 | AB21: 27.518662 | AC21: 28.507418 | AD21: 28.604577 | AE21: 29.061578 | AF21: 29.793079 | AG21: 32.036228 | AH21: 32.832313 | AI21: 31.938557 | AJ21: 33.799237 | AK21: 35.027466 | AL21: 33.315849 | AM21: 33.632103 | AN21: 33.368503 | AO21: 33.487973 | AP21: 32.007821 | AQ21: 31.553939 | AR21: 31.536299 | AS21: 32.004597 | AT21: 29.911479 | AU21: 29.504919 | AV21: 31.989956 | AW21: 33.811003 | AX21: 33.478908 | AY21: 34.162762 | AZ21: 37.758829 | BA21: 39.816564 | BB21: 39.349483 | BC21: 40.047374 | BD21: 44.393574 | BE21: 42.688954 | BF21: 43.238594 | BG21: 45.054563 | BH21: 43.697404 | BI21: 42.40618 | BJ21: 51.195831 | BK21: 48.065082 | BL21: 45.380187 | BM21: 46.680631 | BN21: 49.481208 | BO21: 49.9657 | BP21: 49.59908 | BQ21: 42.819064 | BR21: 50.819791 | BS21: 50.86093 | BT21: 52.093785 | BU21: 54.828493 | BV21: 54.88542 | BW21: 55.464773 | BX21: 55.262897 | BY21: 57.581911 | BZ21: 51.00982 | CA21: 50.92821 | CB21: 48.587497 | CC21: 49.275774 | CD21: 51.372393 | CE21: 49.87647 | CF21: 48.123359 | CG21: 50.41721 | CH21: 60.542526 | CI21: 56.331544 | CJ21: 54.616107 | CK21: 56.199324 | CL21: 56.20994 | CM21: 56.505121 | CN21: 56.005592 | CO21: 58.376488 | CP21: 59.344447 | CQ21: 56.262263 | CR21: 57.231443 | CS21: 60.702256 | CT21: 62.478328 | CU21: 60.977963 | CV21: 59.853038 | CW21: 62.305155 | CX21: 65.132405 | CY21: 64.052829 | CZ21: 61.633043 | DA21: 64.655286 | DD21: =(SUM(CX21:DA21)/SUM(CT21:CW21)-1)*100 -> 4.0140466 | DE21: =+SUM(CX21:DA22)/SUM(CT21:CW22)-1 -> 0.032742789 | DG21: =+SUM(CT21:CW21) -> 245.61448 | DH21: =+SUM(CX21:DA21) -> 255.47356
A22: Eau et Assainissement | B22: 17.689041 | C22: 17.848983 | D22: 17.570292 | E22: 18.197101 | F22: 18.526189 | G22: 18.381634 | H22: 18.48049 | I22: 18.975475 | J22: 18.982696 | K22: 18.692556 | L22: 19.075496 | M22: 18.92212 | N22: 16.945461 | O22: 17.335794 | P22: 19.005571 | Q22: 19.624997 | R22: 18.787914 | S22: 18.35125 | T22: 19.107292 | U22: 21.998355 | V22: 22.228843 | W22: 21.69973 | X22: 23.18188 | Y22: 23.935971 | Z22: 22.222943 | AA22: 22.776752 | AB22: 22.439397 | AC22: 22.723333 | AD22: 22.620224 | AE22: 22.63381 | AF22: 22.701068 | AG22: 23.354787 | AH22: 23.269691 | AI22: 22.664657 | AJ22: 23.326662 | AK22: 23.878751 | AL22: 23.406451 | AM22: 23.756935 | AN22: 23.871325 | AO22: 24.15029 | AP22: 23.753993 | AQ22: 23.789973 | AR22: 24.016702 | AS22: 24.465396 | AT22: 23.728298 | AU22: 23.614128 | AV22: 24.679286 | AW22: 25.256987 | AX22: 24.709449 | AY22: 24.665912 | AZ22: 25.843797 | BA22: 26.397775 | BB22: 25.978565 | BC22: 26.194882 | BD22: 27.924586 | BE22: 27.583626 | BF22: 28.191398 | BG22: 26.740176 | BH22: 27.761031 | BI22: 29.867063 | BJ22: 29.099212 | BK22: 29.08521 | BL22: 29.225567 | BM22: 30.722874 | BN22: 31.335338 | BO22: 32.043694 | BP22: 32.42911 | BQ22: 33.49742 | BR22: 32.075093 | BS22: 31.581731 | BT22: 30.608981 | BU22: 32.197194 | BV22: 30.966704 | BW22: 32.407036 | BX22: 33.057365 | BY22: 33.272894 | BZ22: 32.575942 | CA22: 33.0629 | CB22: 33.482614 | CC22: 33.843528 | CD22: 33.509837 | CE22: 33.586829 | CF22: 33.364299 | CG22: 34.846033 | CH22: 33.963302 | CI22: 35.163265 | CJ22: 35.549706 | CK22: 34.452116 | CL22: 34.819344 | CM22: 34.835175 | CN22: 35.521309 | CO22: 34.056783 | CP22: 34.796321 | CQ22: 35.867955 | CR22: 37.14272 | CS22: 35.139517 | CT22: 35.987564 | CU22: 36.991029 | CV22: 37.19791 | CW22: 36.446086 | CX22: 37.133792 | CY22: 37.653274 | CZ22: 38.017786 | DA22: 36.801593 | DD22: =(SUM(CX22:DA22)/SUM(CT22:CW22)-1)*100 -> 2.0350588 | DG22: =+SUM(CT22:CW22) -> 146.62259 | DH22: =+SUM(CX22:DA22) -> 149.60644
A23: BTP | B23: 105.09153 | C23: 108.51249 | D23: 98.085382 | E23: 105.252 | F23: 107.81651 | G23: 115.72941 | H23: 112.62991 | I23: 99.726899 | J23: 113.17535 | K23: 117.30826 | L23: 104.56485 | M23: 112.96814 | N23: 137.73907 | O23: 140.52521 | P23: 146.27254 | Q23: 133.4616 | R23: 136.3284 | S23: 144.15855 | T23: 150.10203 | U23: 119.66639 | V23: 152.61042 | W23: 184.69002 | X23: 160.41255 | Y23: 153.12519 | Z23: 172.67868 | AA23: 173.17042 | AB23: 166.89546 | AC23: 155.3291 | AD23: 178.72766 | AE23: 177.38542 | AF23: 173.15473 | AG23: 175.2622 | AH23: 178.62978 | AI23: 174.5783 | AJ23: 175.0892 | AK23: 154.9754 | AL23: 162.94333 | AM23: 188.48775 | AN23: 170.65615 | AO23: 144.30916 | AP23: 164.48738 | AQ23: 165.11303 | AR23: 165.8867 | AS23: 156.78081 | AT23: 184.81452 | AU23: 184.50939 | AV23: 178.77982 | AW23: 167.91021 | AX23: 203.65691 | AY23: 175.18736 | AZ23: 197.30001 | BA23: 188.33831 | BB23: 201.07179 | BC23: 215.9889 | BD23: 207.00793 | BE23: 168.30478 | BF23: 252.09069 | BG23: 194.81221 | BH23: 217.56142 | BI23: 170.49143 | BJ23: 203.35889 | BK23: 209.8759 | BL23: 223.54495 | BM23: 240.26437 | BN23: 205.02568 | BO23: 199.24044 | BP23: 239.29754 | BQ23: 283.53442 | BR23: 253.15284 | BS23: 286.4458 | BT23: 252.92333 | BU23: 245.78702 | BV23: 270.79527 | BW23: 291.59454 | BX23: 306.63025 | BY23: 257.09094 | BZ23: 303.03741 | CA23: 314.52329 | CB23: 300.12741 | CC23: 296.5147 | CD23: 319.35646 | CE23: 326.81348 | CF23: 332.2382 | CG23: 332.05991 | CH23: 324.38808 | CI23: 346.81272 | CJ23: 360.61883 | CK23: 365.45542 | CL23: 344.5171 | CM23: 379.60127 | CN23: 349.04039 | CO23: 361.44971 | CP23: 352.4034 | CQ23: 399.20853 | CR23: 365.15874 | CS23: 378.50257 | CT23: 380.25348 | CU23: 407.18134 | CV23: 374.76816 | CW23: 394.67391 | CX23: 391.78816 | CY23: 423.12551 | CZ23: 388.80062 | DA23: 421.87046 | DD23: =(SUM(CX23:DA23)/SUM(CT23:CW23)-1)*100 -> 4.4131851 | DG23: =+SUM(CT23:CW23) -> 1556.8769 | DH23: =+SUM(CX23:DA23) -> 1625.5848
A24: Secteur tertiaire | B24: 1000.733 | C24: 1031.0029 | D24: 995.13981 | E24: 996.49318 | F24: 1031.8451 | G24: 1064.2678 | H24: 1059.7515 | I24: 1080.394 | J24: 1108.6865 | K24: 1129.5152 | L24: 1129.2492 | M24: 1137.0172 | N24: 1130.5737 | O24: 1139.9914 | P24: 1157.5675 | Q24: 1175.7224 | R24: 1189.9205 | S24: 1234.1184 | T24: 1266.9762 | U24: 1313.0132 | V24: 1329.2211 | W24: 1356.9737 | X24: 1372.5969 | Y24: 1425.2118 | Z24: 1432.5938 | AA24: 1463.9326 | AB24: 1489.2635 | AC24: 1482.9653 | AD24: 1481.2468 | AE24: 1490.0978 | AF24: 1511.4873 | AG24: 1589.1413 | AH24: 1572.8544 | AI24: 1623.6606 | AJ24: 1657.7793 | AK24: 1681.0415 | AL24: 1705.6416 | AM24: 1742.1212 | AN24: 1749.3201 | AO24: 1769.6311 | AP24: 1798.4898 | AQ24: 1824.6478 | AR24: 1833.5052 | AS24: 1847.6325 | AT24: 1862.827 | AU24: 1891.9891 | AV24: 1926.9137 | AW24: 1964.0288 | AX24: 1965.1377 | AY24: 2007.7817 | AZ24: 2055.8833 | BA24: 2100.75 | BB24: 2113.1739 | BC24: 2073.1745 | BD24: 2088.3486 | BE24: 2103.2609 | BF24: 2144.7467 | BG24: 2192.2947 | BH24: 2221.7357 | BI24: 2266.4548 | BJ24: 2318.7477 | BK24: 2309.5268 | BL24: 2331.6238 | BM24: 2421.0049 | BN24: 2386.1787 | BO24: 2407.9931 | BP24: 2439.4744 | BQ24: 2450.2399 | BR24: 2480.474 | BS24: 2501.0784 | BT24: 2530.9737 | BU24: 2600.2289 | BV24: 2594.8559 | BW24: 2631.6854 | BX24: 2654.8935 | BY24: 2712.5772 | BZ24: 2724.8359 | CA24: 2777.4071 | CB24: 2780.1839 | CC24: 2851.2964 | CD24: 2840.6728 | CE24: 2878.7848 | CF24: 2866.3544 | CG24: 2898.3325 | CH24: 2860.8338 | CI24: 2809.2379 | CJ24: 2863.2021 | CK24: 2891.5575 | CL24: 2906.8145 | CM24: 2918.9642 | CN24: 2946.8489 | CO24: 2997.1085 | CP24: 3031.552 | CQ24: 3038.1672 | CR24: 3069.9375 | CS24: 3093.2545 | CT24: 3141.6647 | CU24: 3165.6338 | CV24: 3169.3396 | CW24: 3237.0397 | CX24: 3274.038 | CY24: 3266.9258 | CZ24: 3310.4324 | DA24: 3430.1798 | DD24: =(SUM(CX24:DA24)/SUM(CT24:CW24)-1)*100 -> 4.4668282 | DG24: =+SUM(CT24:CW24) -> 12713.678 | DH24: =+SUM(CX24:DA24) -> 13281.576
A25: Commerce et réparation | B25: 198.56165 | C25: 209.27186 | D25: 196.55142 | E25: 197.68475 | F25: 205.63582 | G25: 224.24878 | H25: 210.13992 | I25: 214.12346 | J25: 223.88475 | K25: 229.14334 | L25: 221.91619 | M25: 224.23396 | N25: 216.68517 | O25: 227.49087 | P25: 231.93497 | Q25: 232.36172 | R25: 222.36242 | S25: 235.86513 | T25: 240.7024 | U25: 263.22728 | V25: 260.24501 | W25: 274.15527 | X25: 274.65296 | Y25: 294.86355 | Z25: 271.57261 | AA25: 275.42077 | AB25: 282.12417 | AC25: 279.78849 | AD25: 281.00145 | AE25: 287.35747 | AF25: 292.60372 | AG25: 333.96705 | AH25: 285.19621 | AI25: 299.16684 | AJ25: 315.61787 | AK25: 331.1625 | AL25: 348.32151 | AM25: 380.14933 | AN25: 380.29252 | AO25: 383.70411 | AP25: 385.39163 | AQ25: 390.44107 | AR25: 386.17011 | AS25: 400.54842 | AT25: 411.02352 | AU25: 433.03445 | AV25: 446.69669 | AW25: 452.79013 | AX25: 429.43819 | AY25: 434.20712 | AZ25: 448.2524 | BA25: 465.76908 | BB25: 473.06523 | BC25: 473.12507 | BD25: 464.43406 | BE25: 454.48627 | BF25: 485.46177 | BG25: 492.56112 | BH25: 494.26317 | BI25: 509.42127 | BJ25: 506.62846 | BK25: 527.12273 | BL25: 518.34039 | BM25: 565.25985 | BN25: 520.14737 | BO25: 532.12204 | BP25: 531.06626 | BQ25: 525.79979 | BR25: 530.68432 | BS25: 555.0249 | BT25: 553.25278 | BU25: 598.115 | BV25: 563.23222 | BW25: 588.70928 | BX25: 599.70664 | BY25: 584.17686 | BZ25: 599.10555 | CA25: 633.78193 | CB25: 608.86939 | CC25: 618.14728 | CD25: 613.88418 | CE25: 647.40967 | CF25: 620.21737 | CG25: 648.22408 | CH25: 610.49416 | CI25: 619.37009 | CJ25: 620.44935 | CK25: 626.44327 | CL25: 640.7057 | CM25: 645.19207 | CN25: 631.6621 | CO25: 630.96375 | CP25: 634.25653 | CQ25: 650.75677 | CR25: 667.8472 | CS25: 656.64251 | CT25: 652.23172 | CU25: 698.56563 | CV25: 667.6057 | CW25: 665.81838 | CX25: 676.47203 | CY25: 710.7254 | CZ25: 693.8077 | DA25: 701.09247 | DD25: =(SUM(CX25:DA25)/SUM(CT25:CW25)-1)*100 -> 3.6463523 | DG25: =+SUM(CT25:CW25) -> 2684.2214 | DH25: =+SUM(CX25:DA25) -> 2782.0976
A26: Transports | B26: 220.52392 | C26: 220.628 | D26: 220.84956 | E26: 221.21715 | F26: 234.74454 | G26: 240.80622 | H26: 244.80359 | I26: 246.4567 | J26: 245.8691 | K26: 245.3339 | L26: 245.03731 | M26: 245.06363 | N26: 245.46033 | O26: 247.7732 | P26: 251.87659 | Q26: 257.79683 | R26: 265.71364 | S26: 273.25444 | T26: 280.01602 | U26: 285.7408 | V26: 290.40516 | W26: 296.14303 | X26: 303.20474 | Y26: 312.06867 | Z26: 323.58598 | AA26: 331.88015 | AB26: 336.19299 | AC26: 336.08823 | AD26: 331.43608 | AE26: 329.7536 | AF26: 330.8837 | AG26: 334.79578 | AH26: 341.25862 | AI26: 345.95367 | AJ26: 348.7827 | AK26: 349.73726 | AL26: 348.94421 | AM26: 349.68225 | AN26: 351.99274 | AO26: 355.78134 | AP26: 361.03788 | AQ26: 366.06892 | AR26: 371.06761 | AS26: 376.14416 | AT26: 381.43648 | AU26: 386.2794 | AV26: 390.63277 | AW26: 394.45705 | AX26: 398.20217 | AY26: 401.08482 | AZ26: 403.32846 | BA26: 404.90641 | BB26: 406.03357 | BC26: 396.59163 | BD26: 412.47438 | BE26: 424.31044 | BF26: 423.01202 | BG26: 431.62616 | BH26: 437.01347 | BI26: 447.01319 | BJ26: 452.93709 | BK26: 451.26891 | BL26: 453.31311 | BM26: 478.04899 | BN26: 475.67341 | BO26: 499.90218 | BP26: 519.09281 | BQ26: 503.49119 | BR26: 508.22148 | BS26: 503.96183 | BT26: 507.16012 | BU26: 524.23356 | BV26: 528.72717 | BW26: 531.60896 | BX26: 524.4036 | BY26: 545.05726 | BZ26: 554.02471 | CA26: 553.23345 | CB26: 553.32273 | CC26: 563.9998 | CD26: 572.27516 | CE26: 582.10087 | CF26: 580.07751 | CG26: 582.36736 | CH26: 587.76392 | CI26: 562.22977 | CJ26: 579.95086 | CK26: 577.07076 | CL26: 580.10627 | CM26: 582.93033 | CN26: 588.91171 | CO26: 591.62405 | CP26: 594.81995 | CQ26: 615.4929 | CR26: 629.43681 | CS26: 637.29493 | CT26: 643.62308 | CU26: 632.62866 | CV26: 642.40244 | CW26: 662.57275 | CX26: 651.63419 | CY26: 655.61318 | CZ26: 659.35972 | DA26: 673.99978 | DD26: =(SUM(CX26:DA26)/SUM(CT26:CW26)-1)*100 -> 2.300454 | DE26: =+SUM(CX26:DA27)/SUM(CT26:CW27)-1 -> 0.03085146 | DG26: =+SUM(CT26:CW26) -> 2581.2269 | DH26: =+SUM(CX26:DA26) -> 2640.6069
A27: Information et communication | B27: 13.822012 | C27: 14.181944 | D27: 14.905939 | E27: 16.001912 | F27: 16.399793 | G27: 17.440469 | H27: 18.678501 | I27: 20.150486 | J27: 21.907437 | K27: 22.917429 | L27: 23.133625 | M27: 22.582872 | N27: 21.471874 | O27: 21.119925 | P27: 21.515361 | Q27: 22.688201 | R27: 24.760282 | S27: 26.781694 | T27: 28.737862 | U27: 30.571617 | V27: 32.083654 | W27: 34.314267 | X27: 37.496291 | Y27: 42.037387 | Z27: 48.740609 | AA27: 54.832863 | AB27: 59.367021 | AC27: 61.468853 | AD27: 60.960919 | AE27: 61.764405 | AF27: 63.846156 | AG27: 67.273815 | AH27: 72.583259 | AI27: 76.745544 | AJ27: 79.73711 | AK27: 81.43253 | AL27: 81.80531 | AM27: 81.84571 | AN27: 81.608178 | AO27: 81.093636 | AP27: 80.297318 | AQ27: 80.14194 | AR27: 80.641374 | AS27: 81.793138 | AT27: 83.598501 | AU27: 84.233804 | AV27: 83.651932 | AW27: 81.752828 | AX27: 78.390186 | AY27: 81.283043 | AZ27: 90.832021 | BA27: 107.12906 | BB27: 79.328393 | BC27: 84.261267 | BD27: 96.890424 | BE27: 102.60195 | BF27: 92.256646 | BG27: 92.627677 | BH27: 99.007692 | BI27: 99.071134 | BJ27: 106.41059 | BK27: 94.44603 | BL27: 104.61142 | BM27: 102.9276 | BN27: 102.85645 | BO27: 101.5914 | BP27: 102.65821 | BQ27: 103.11631 | BR27: 109.7358 | BS27: 111.51044 | BT27: 112.39276 | BU27: 114.54699 | BV27: 119.68574 | BW27: 120.11984 | BX27: 120.86768 | BY27: 118.56974 | BZ27: 120.22837 | CA27: 117.38659 | CB27: 117.2657 | CC27: 121.65118 | CD27: 122.10628 | CE27: 114.73017 | CF27: 120.87884 | CG27: 126.49314 | CH27: 127.87731 | CI27: 116.48037 | CJ27: 125.23121 | CK27: 138.70567 | CL27: 130.72879 | CM27: 125.04222 | CN27: 125.30644 | CO27: 140.34726 | CP27: 144.62994 | CQ27: 133.54592 | CR27: 134.93214 | CS27: 145.29471 | CT27: 160.34994 | CU27: 148.74565 | CV27: 140.83426 | CW27: 163.29175 | CX27: 170.91634 | CY27: 156.44789 | CZ27: 148.25027 | DA27: 176.78056 | DD27: =(SUM(CX27:DA27)/SUM(CT27:CW27)-1)*100 -> 6.3881416 | DG27: =+SUM(CT27:CW27) -> 613.2216 | DH27: =+SUM(CX27:DA27) -> 652.39506
A28: Hébergement et restauration | B28: 78.956347 | C28: 79.586068 | D28: 80.857531 | E28: 82.79524 | F28: 84.046911 | G28: 85.462409 | H28: 86.38829 | I28: 86.807468 | J28: 86.822272 | K28: 87.622234 | L28: 89.301556 | M28: 91.924243 | N28: 95.835975 | O28: 99.212801 | P28: 102.03925 | Q28: 104.20966 | R28: 105.64485 | S28: 107.31608 | T28: 109.29164 | U28: 111.6458 | V28: 114.50232 | W28: 116.96381 | X28: 118.96505 | Y28: 120.42963 | Z28: 121.13465 | AA28: 123.02395 | AB28: 126.04697 | AC28: 130.07647 | AD28: 134.91383 | AE28: 138.46147 | AF28: 141.11992 | AG28: 143.02735 | AH28: 144.22066 | AI28: 145.42098 | AJ28: 146.5725 | AK28: 147.66455 | AL28: 148.7448 | AM28: 150.22068 | AN28: 152.08136 | AO28: 154.30079 | AP28: 156.79883 | AQ28: 159.32071 | AR28: 161.90014 | AS28: 164.56105 | AT28: 166.99475 | AU28: 170.28776 | AV28: 174.37688 | AW28: 179.31084 | AX28: 185.94962 | AY28: 189.31849 | AZ28: 189.6516 | BA28: 186.65445 | BB28: 205.52533 | BC28: 205.0285 | BD28: 201.83692 | BE28: 207.86134 | BF28: 211.0249 | BG28: 215.63738 | BH28: 207.50827 | BI28: 215.77542 | BJ28: 221.38279 | BK28: 223.80566 | BL28: 219.47991 | BM28: 232.62287 | BN28: 238.48521 | BO28: 227.74428 | BP28: 228.24443 | BQ28: 236.36163 | BR28: 236.93578 | BS28: 240.03922 | BT28: 243.79243 | BU28: 255.87957 | BV28: 250.78882 | BW28: 255.51875 | BX28: 260.57681 | BY28: 270.76263 | BZ28: 269.46826 | CA28: 268.95672 | CB28: 270.15414 | CC28: 283.36034 | CD28: 286.10826 | CE28: 282.51891 | CF28: 283.05058 | CG28: 285.97323 | CH28: 271.43856 | CI28: 248.80446 | CJ28: 254.24688 | CK28: 267.05363 | CL28: 281.94426 | CM28: 275.74621 | CN28: 285.54066 | CO28: 299.20666 | CP28: 298.77166 | CQ28: 294.76222 | CR28: 301.60043 | CS28: 294.32932 | CT28: 309.38343 | CU28: 304.5794 | CV28: 316.96041 | CW28: 315.60697 | CX28: 320.14997 | CY28: 315.04166 | CZ28: 325.82229 | DA28: 352.86822 | DD28: =(SUM(CX28:DA28)/SUM(CT28:CW28)-1)*100 -> 5.403152 | DE28: =+SUM(CX28:DA28,CX25:DA25)/SUM(CT28:CW28,CT25:CW25)-1 -> 0.042034732 | DG28: =+SUM(CT28:CW28) -> 1246.5302 | DH28: =+SUM(CX28:DA28) -> 1313.8821
A29: Services financiers | B29: 34.08435 | C29: 35.228478 | D29: 35.074681 | E29: 36.764878 | F29: 36.264135 | G29: 36.472969 | H29: 36.115392 | I29: 37.185271 | J29: 34.108263 | K29: 33.83703 | L29: 35.278548 | M29: 37.051996 | N29: 37.555355 | O29: 39.472446 | P29: 44.147741 | Q29: 47.71562 | R29: 49.194949 | S29: 51.247361 | T29: 51.736259 | U29: 52.186046 | V29: 49.971923 | W29: 46.977822 | X29: 46.184043 | Y29: 47.83229 | Z29: 52.512875 | AA29: 52.299429 | AB29: 52.465602 | AC29: 51.139716 | AD29: 47.495537 | AE29: 44.694515 | AF29: 42.953689 | AG29: 46.329297 | AH29: 47.896646 | AI29: 49.749848 | AJ29: 53.213754 | AK29: 56.810544 | AL29: 60.678106 | AM29: 61.19057 | AN29: 61.671137 | AO29: 67.082877 | AP29: 65.381474 | AQ29: 63.689438 | AR29: 63.869463 | AS29: 61.394406 | AT29: 63.796068 | AU29: 63.599583 | AV29: 66.656107 | AW29: 77.142504 | AX29: 87.446628 | AY29: 99.725175 | AZ29: 105.07505 | BA29: 100.75916 | BB29: 85.888502 | BC29: 78.807971 | BD29: 74.289246 | BE29: 71.466977 | BF29: 77.434535 | BG29: 82.019977 | BH29: 86.72328 | BI29: 88.911458 | BJ29: 86.903006 | BK29: 87.309689 | BL29: 85.501315 | BM29: 87.224238 | BN29: 87.052132 | BO29: 90.41929 | BP29: 96.365774 | BQ29: 99.955799 | BR29: 98.441032 | BS29: 98.554794 | BT29: 101.16937 | BU29: 103.73281 | BV29: 103.95756 | BW29: 104.67404 | BX29: 105.40686 | BY29: 107.93954 | BZ29: 113.12307 | CA29: 118.72577 | CB29: 122.79461 | CC29: 125.4363 | CD29: 124.69389 | CE29: 123.88904 | CF29: 122.63272 | CG29: 124.30292 | CH29: 127.51399 | CI29: 127.04792 | CJ29: 125.95799 | CK29: 128.68039 | CL29: 137.91744 | CM29: 140.82695 | CN29: 138.15636 | CO29: 139.21616 | CP29: 155.27155 | CQ29: 150.34427 | CR29: 142.29892 | CS29: 143.80311 | CT29: 163.7922 | CU29: 162.07846 | CV29: 154.95471 | CW29: 160.29643 | CX29: 183.36761 | CY29: 176.7805 | CZ29: 167.34172 | DA29: 178.13697 | DD29: =(SUM(CX29:DA29)/SUM(CT29:CW29)-1)*100 -> 10.061268 | DG29: =+SUM(CT29:CW29) -> 641.12181 | DH29: =+SUM(CX29:DA29) -> 705.6268
A30: Administrations publiques | B30: 183.20541 | C30: 196.07203 | D30: 178.56968 | E30: 175.6245 | F30: 184.33198 | G30: 190.63943 | H30: 191.46952 | I30: 194.18973 | J30: 202.17658 | K30: 206.82881 | L30: 208.74903 | M30: 211.87832 | N30: 207.52579 | O30: 203.03338 | P30: 203.23389 | Q30: 205.44717 | R30: 210.16681 | S30: 218.16214 | T30: 226.92103 | U30: 234.96484 | V30: 239.97178 | W30: 238.82555 | X30: 234.69498 | Y30: 237.45015 | Z30: 240.61476 | AA30: 243.81247 | AB30: 248.63105 | AC30: 247.36222 | AD30: 250.66902 | AE30: 257.56992 | AF30: 265.30053 | AG30: 273.26455 | AH30: 285.63323 | AI30: 297.88609 | AJ30: 301.11934 | AK30: 307.82999 | AL30: 314.58893 | AM30: 322.20262 | AN30: 329.86377 | AO30: 334.8976 | AP30: 343.46889 | AQ30: 353.67072 | AR30: 359.62448 | AS30: 360.79478 | AT30: 360.91857 | AU30: 365.54839 | AV30: 372.77432 | AW30: 375.90056 | AX30: 384.54341 | AY30: 391.48137 | AZ30: 400.16492 | BA30: 418.0788 | BB30: 425.20456 | BC30: 419.06775 | BD30: 418.66149 | BE30: 416.94834 | BF30: 422.3034 | BG30: 441.79483 | BH30: 451.07201 | BI30: 463.78526 | BJ30: 473.35304 | BK30: 478.68344 | BL30: 494.15098 | BM30: 498.86569 | BN30: 496.2644 | BO30: 483.22199 | BP30: 477.23548 | BQ30: 490.47738 | BR30: 505.44907 | BS30: 504.00365 | BT30: 507.86857 | BU30: 497.08371 | BV30: 525.5221 | BW30: 516.64017 | BX30: 514.31132 | BY30: 534.43941 | BZ30: 531.40421 | CA30: 536.66996 | CB30: 543.93152 | CC30: 557.36314 | CD30: 557.634 | CE30: 560.08177 | CF30: 561.28194 | CG30: 547.49394 | CH30: 564.13151 | CI30: 567.79691 | CJ30: 571.69628 | CK30: 567.85448 | CL30: 569.18748 | CM30: 582.82243 | CN30: 591.08536 | CO30: 590.87334 | CP30: 610.92337 | CQ30: 604.94784 | CR30: 592.54939 | CS30: 606.93745 | CT30: 613.91556 | CU30: 617.09429 | CV30: 625.61251 | CW30: 634.76606 | CX30: 651.69173 | CY30: 625.30132 | CZ30: 664.97341 | DA30: 690.45309 | DD30: =(SUM(CX30:DA30)/SUM(CT30:CW30)-1)*100 -> 5.6607447 | DG30: =+SUM(CT30:CW30) -> 2491.3884 | DH30: =+SUM(CX30:DA30) -> 2632.4196
A31: Autres services marchands | B31: 307.69442 | C31: 311.246 | D31: 302.79627 | E31: 299.47648 | F31: 305.7686 | G31: 304.36572 | H31: 305.46797 | I31: 313.55003 | J31: 321.66642 | K31: 329.55632 | L31: 330.29349 | M31: 329.36406 | N31: 333.12046 | O31: 330.34968 | P31: 332.61316 | Q31: 335.58638 | R31: 340.62457 | S31: 348.86588 | T31: 354.90725 | U31: 358.03491 | V31: 363.30141 | W31: 367.69832 | X31: 372.37929 | Y31: 381.76016 | Z31: 384.51867 | AA31: 388.40849 | AB31: 386.49441 | AC31: 375.79563 | AD31: 375.7223 | AE31: 369.83547 | AF31: 372.60744 | AG31: 387.09699 | AH31: 393.92833 | AI31: 405.78685 | AJ31: 409.30349 | AK31: 402.93981 | AL31: 398.90054 | AM31: 392.09054 | AN31: 387.90869 | AO31: 390.042 | AP31: 403.54631 | AQ31: 408.97351 | AR31: 408.59193 | AS31: 400.1109 | AT31: 392.82188 | AU31: 386.71793 | AV31: 390.28253 | AW31: 401.897 | AX31: 402.67303 | AY31: 412.62788 | AZ31: 419.23989 | BA31: 415.90185 | BB31: 439.22687 | BC31: 416.14986 | BD31: 418.15642 | BE31: 423.01666 | BF31: 432.16425 | BG31: 436.21924 | BH31: 445.92868 | BI31: 443.38081 | BJ31: 469.66804 | BK31: 448.93439 | BL31: 457.14064 | BM31: 458.90126 | BN31: 466.35437 | BO31: 473.10303 | BP31: 484.04017 | BQ31: 490.55599 | BR31: 491.27659 | BS31: 488.51407 | BT31: 505.15095 | BU31: 506.0234 | BV31: 502.9423 | BW31: 514.41432 | BX31: 529.62059 | BY31: 551.63179 | BZ31: 537.52459 | CA31: 549.34103 | CB31: 563.65208 | CC31: 580.91613 | CD31: 563.17254 | CE31: 568.32797 | CF31: 577.73583 | CG31: 584.29369 | CH31: 572.62257 | CI31: 569.20601 | CJ31: 587.72716 | CK31: 587.53838 | CL31: 567.46325 | CM31: 568.06229 | CN31: 586.59979 | CO31: 604.92352 | CP31: 594.8591 | CQ31: 589.32937 | CR31: 601.25663 | CS31: 610.21963 | CT31: 602.82132 | CU31: 602.33017 | CV31: 621.62047 | CW31: 639.61068 | CX31: 628.90781 | CY31: 630.77777 | CZ31: 653.45823 | DA31: 663.83099 | DD31: =(SUM(CX31:DA31)/SUM(CT31:CW31)-1)*100 -> 4.483982 | DE31: =+SUM(CX31:DA31,CX29:DA29)/SUM(CT31:CW31,CT29:CW29)-1 -> 0.056346545 | DG31: =+SUM(CT31:CW31) -> 2466.3826 | DH31: =+SUM(CX31:DA31) -> 2576.9748
A32: TOTAL DES VA | B32: 2247.9274 | C32: 2374.3958 | D32: 2243.5127 | E32: 2239.3044 | F32: 2292.7577 | G32: 2424.5727 | H32: 2361.7008 | I32: 2354.8112 | J32: 2417.1598 | K32: 2518.7988 | L32: 2450.0427 | M32: 2459.3937 | N32: 2518.8231 | O32: 2596.241 | P32: 2621.8933 | Q32: 2630.2511 | R32: 2592.6275 | S32: 2719.9565 | T32: 2758.9568 | U32: 2841.9243 | V32: 2867.9604 | W32: 3003.7102 | X32: 2979.7888 | Y32: 3000.1325 | Z32: 2970.5789 | AA32: 3022.4642 | AB32: 3055.6512 | AC32: 3020.6214 | AD32: 2990.1211 | AE32: 3076.2553 | AF32: 3112.0667 | AG32: 3278.2215 | AH32: 3168.3346 | AI32: 3248.8355 | AJ32: 3298.1312 | AK32: 3284.9558 | AL32: 3333.3585 | AM32: 3437.8673 | AN32: 3370.2575 | AO32: 3390.8743 | AP32: 3421.8813 | AQ32: 3485.1232 | AR32: 3487.31 | AS32: 3513.7623 | AT32: 3497.6293 | AU32: 3580.2561 | AV32: 3602.7359 | AW32: 3641.3053 | AX32: 3620.4702 | AY32: 3668.481 | AZ32: 3745.2026 | BA32: 3794.8503 | BB32: 3864.9812 | BC32: 3889.9921 | BD32: 3877.8612 | BE32: 3803.6818 | BF32: 3994.5245 | BG32: 4012.1541 | BH32: 4062.7613 | BI32: 4062.8331 | BJ32: 4124.7932 | BK32: 4185.1966 | BL32: 4215.9965 | BM32: 4376.4696 | BN32: 4294.1151 | BO32: 4397.2366 | BP32: 4459.9643 | BQ32: 4507.8041 | BR32: 4481.9019 | BS32: 4626.2349 | BT32: 4598.2094 | BU32: 4697.3268 | BV32: 4680.7043 | BW32: 4802.8902 | BX32: 4799.455 | BY32: 4757.0405 | BZ32: 4872.9667 | CA32: 5045.855 | CB32: 4936.4256 | CC32: 5001.9419 | CD32: 5019.8542 | CE32: 5221.0946 | CF32: 5139.0783 | CG32: 5160.6139 | CH32: 5104.8635 | CI32: 5136.4508 | CJ32: 5176.9865 | CK32: 5265.5156 | CL32: 5251.7394 | CM32: 5379.5538 | CN32: 5333.3091 | CO32: 5388.8871 | CP32: 5447.0449 | CQ32: 5621.7667 | CR32: 5530.8848 | CS32: 5539.3261 | CT32: 5590.8621 | CU32: 5788.0711 | CV32: 5698.5398 | CW32: 5756.6957 | CX32: 5809.9585 | CY32: 5914.6913 | CZ32: 5884.9863 | DA32: 5995.9106 | DD32: =(SUM(CX32:DA32)/SUM(CT32:CW32)-1)*100 -> 3.3781744 | DG32: =+SUM(CT32:CW32) -> 22834.169 | DH32: =+SUM(CX32:DA32) -> 23605.547
