Workbook

Sheet IPC
B2: IPC NATIONAL
A4: N° | B4: POSTES DE CONSOMMATION | C4: Pondération | D4: 40544 | E4: 40575 | F4: 40603 | G4: 40634 | H4: 40664 | I4: 40695 | J4: 40725 | K4: 40756 | L4: 40787 | M4: 40817 | N4: 40848 | O4: 40878 | P4: 40909 | Q4: 40940 | R4: 40969 | S4: 41000 | T4: 41030 | U4: 41061 | V4: 41091 | W4: 41122 | X4: 41153 | Y4: 41183 | Z4: 41214 | AA4: 41244 | AB4: 41275 | AC4: 41306 | AD4: 41334 | AE4: 41365 | AF4: 41395 | AG4: 41426 | AH4: 41456 | AI4: 41487 | AJ4: 41518 | AK4: 41548 | AL4: 41579 | AM4: 41609 | AN4: 41640 | AO4: 41671 | AP4: 41699 | AQ4: 41730 | AR4: 41760 | AS4: 41791 | AT4: 41821 | AU4: 41852 | AV4: 41883 | AW4: 41913 | AX4: 41944 | AY4: 41974 | AZ4: 42005 | BA4: 42036 | BB4: 42064 | BC4: 42095 | BD4: 42125 | BE4: 42156 | BF4: 42186 | BG4: 42217 | BH4: 42248 | BI4: 42278 | BJ4: 42309 | BK4: 42339 | BL4: 42370 | BM4: 42401 | BN4: 42430 | BO4: 42461 | BP4: 42491 | BQ4: 42522 | BR4: 42552 | BS4: 42583 | BT4: 42614 | BU4: 42644 | BV4: 42675 | BW4: 42705 | BX4: 42736 | BY4: 42767 | BZ4: 42795 | CA4: 42826 | CB4: 42856 | CC4: 42887 | CD4: 42917 | CE4: 42948 | CF4: 42979 | CG4: 43009 | CH4: 43040 | CI4: 43070 | CJ4: 43101 | CK4: 43132 | CL4: 43160 | CM4: 43191 | CN4: 43221 | CO4: 43252 | CP4: 43282 | CQ4: 43313 | CR4: 43344 | CS4: 43374 | CT4: 43405 | CU4: 43435 | CV4: 43466 | CW4: 43497 | CX4: 43525 | CY4: 43556 | CZ4: 43586 | DA4: 43617 | DB4: 43647 | DC4: 43678 | DD4: 43709 | DE4: 43739 | DF4: 43770 | DG4: 43800 | DH4: 43831 | DI4: 43862 | DJ4: 43891 | DK4: 43922 | DL4: 43952 | DM4: 43983 | DN4: 44013 | DO4: 44044 | DP4: 44075 | DQ4: 44105 | DR4: 44136 | DS4: 44166 | DT4: 44197 | DU4: 44228 | DV4: 44256 | DW4: 44287 | DX4: 44317 | DY4: 44348 | DZ4: 44378 | EA4: 44409 | EB4: 44440 | EC4: 44470 | ED4: 44501 | EE4: 44531 | EF4: 44562 | EG4: 44593 | EH4: 44621 | EI4: 44652 | EJ4: 44682 | EK4: 44713 | EL4: 44743 | EM4: 44774 | EN4: 44805 | EO4: 44835 | EP4: 44866 | EQ4: 44896 | ER4: 44927 | ES4: 44958 | ET4: 44986 | EU4: 45017 | EV4: 45047 | EW4: 45078 | EX4: 45108 | EY4: 45139 | EZ4: 45170 | FA4: 45200 | FB4: 45231 | FC4: 45261 | FD4: 45292 | FE4: 45323 | FF4: 45352 | FG4: 45383 | FH4: 45413 | FI4: 45444 | FJ4: 45474 | FK4: 45505 | FL4: 45536 | FM4: 45566 | FN4: 45597 | FO4: 45627 | FP4: 45658 | FQ4: 45689 | FR4: 45717 | FS4: 45748 | FT4: 45778 | FU4: 45809 | FV4: 45839 | FW4: 45870 | FX4: 45901 | FY4: 45931 | FZ4: 45962 | GA4: 45992 | GB4: 46023 | GC4: 46054 | GD4: 46082 | GE4: 46113 | GF4: 46143 | GG4: 46174 | GH4: 46204 | GI4: 46235 | GJ4: 46266 | GK4: 46296 | GL4: 46327 | GM4: 46357 | GN4: 46388 | GO4: 46419 | GP4: 46447 | GQ4: 46478 | GR4: 46508 | GS4: 46539 | GT4: 46569 | GU4: 46600 | GV4: 46631 | GW4: 46661 | GX4: 46692 | GY4: 46722 | GZ4: 46753 | HA4: 46784 | HB4: 46813 | HC4: 46844 | HD4: 46874 | HE4: 46905 | HF4: 46935 | HG4: 46966 | HH4: 46997 | HI4: 47027 | HJ4: 47058 | HK4: 47088 | HL4: 47119 | HM4: 47150 | HN4: 47178 | HO4: 47209 | HP4: 47239 | HQ4: 47270 | HR4: 47300 | HS4: 47331 | HT4: 47362 | HU4: 47392 | HV4: 47423 | HW4: 47453 | HX4: 47484 | HY4: 47515 | HZ4: 47543 | IA4: 47574 | IB4: 47604 | IC4: 47635 | ID4: 47665 | IE4: 47696 | IF4: 47727 | IG4: 47757 | IH4: 47788 | II4: 47818
A5: 01 | B5: Produits alimentaires et boissons non alcoolisées | C5: 31.82 | P5: 71.84166 | Q5: 71.789012 | R5: 72.128396 | S5: 72.632914 | T5: 73.182413 | U5: 73.193788 | V5: 73.3626 | W5: 74.212563 | X5: 74.398141 | Y5: 74.937835 | Z5: 74.479839 | AA5: 75.840036 | AB5: 75.412862 | AC5: 74.775307 | AD5: 74.810594 | AE5: 74.736036 | AF5: 75.183802 | AG5: 75.446047 | AH5: 75.438341 | AI5: 76.178604 | AJ5: 76.453543 | AK5: 77.249915 | AL5: 77.505126 | AM5: 77.520042 | AN5: 76.212771 | AO5: 76.069955 | AP5: 75.907807 | AQ5: 75.549267 | AR5: 76.215064 | AS5: 75.678497 | AT5: 76.705816 | AU5: 76.675134 | AV5: 76.712194 | AW5: 76.876815 | AX5: 77.319966 | AY5: 77.681951 | AZ5: 76.863895 | BA5: 76.940349 | BB5: 76.637369 | BC5: 77.462565 | BD5: 77.707416 | BE5: 77.905547 | BF5: 78.89384 | BG5: 78.345032 | BH5: 78.738365 | BI5: 79.284688 | BJ5: 78.579577 | BK5: 78.939786 | BL5: 78.266427 | BM5: 78.418795 | BN5: 78.242375 | BO5: 78.694825 | BP5: 79.633317 | BQ5: 79.078259 | BR5: 79.213265 | BS5: 79.362568 | BT5: 79.463731 | BU5: 78.796402 | BV5: 78.772675 | BW5: 78.459961 | BX5: 77.731096 | BY5: 77.820327 | BZ5: 77.741017 | CA5: 78.72727 | CB5: 78.950019 | CC5: 78.733969 | CD5: 78.911413 | CE5: 79.593182 | CF5: 79.881937 | CG5: 79.4891 | CH5: 79.456672 | CI5: 79.51705 | CJ5: 78.813292 | CK5: 78.811419 | CL5: 79.044574 | CM5: 79.666941 | CN5: 79.886465 | CO5: 79.539217 | CP5: 79.383551 | CQ5: 79.413235 | CR5: 80.156964 | CS5: 80.987485 | CT5: 81.082745 | CU5: 81.262295 | CV5: 80.365833 | CW5: 81.09557 | CX5: 81.455064 | CY5: 81.842484 | CZ5: 81.75196 | DA5: 82.017117 | DB5: 82.469871 | DC5: 82.451301 | DD5: 82.733529 | DE5: 82.971556 | DF5: 83.174303 | DG5: 83.490798 | DH5: 83.591848 | DI5: 83.716979 | DJ5: 84.293081 | DK5: 83.942304 | DL5: 84.19006 | DM5: 84.725467 | DN5: 85.8246 | DO5: 85.847561 | DP5: 85.828591 | DQ5: 86.371325 | DR5: 86.152645 | DS5: 86.402125 | DT5: 85.816699 | DU5: 86.057771 | DV5: 86.775437 | DW5: 87.357455 | DX5: 87.878105 | DY5: 88.578343 | DZ5: 89.646956 | EA5: 89.50762 | EB5: 89.674705 | EC5: 89.888768 | ED5: 90.189511 | EE5: 92.943869 | EF5: 93.539655 | EG5: 94.464877 | EH5: 95.357029 | EI5: 97.681808 | EJ5: 98.596401 | EK5: 99.167402 | EL5: 100.78546 | EM5: 102.42192 | EN5: 103.51916 | EO5: 103.77181 | EP5: 105.01665 | EQ5: 105.67783 | ER5: 106.56448 | ES5: 107.11903 | ET5: 107.40921 | EU5: 108.74476 | EV5: 109.79452 | EW5: 110.92696 | EX5: 111.85555 | EY5: 113.26514 | EZ5: 113.56159 | FA5: 113.95339 | FB5: 113.51648 | FC5: 113.23401 | FD5: 112.2 | FE5: 113 | FF5: 113.8 | FG5: 115.1 | FH5: 115.6 | FI5: 116.6 | FJ5: 116.6322 | FK5: 117.86557 | FL5: 120.11619 | FM5: 120.50318 | FN5: 120.10243 | FO5: 121.6998 | FP5: 121.1 | FQ5: 121.2 | FR5: 122 | FS5: 123.50832 | FT5: 124.2038 | FU5: 124.89928 | FV5: 125.59476 | FW5: 126.29024 | FX5: 126.98572 | FY5: 127.6812 | FZ5: 128.37668 | GA5: 129.07216 | GB5: 129.76764 | GC5: 130.46312 | GD5: 131.1586 | GE5: 131.85408 | GF5: 132.54957 | GG5: 133.24505 | GH5: 133.94053 | GI5: 134.63601 | GJ5: 135.33149 | GK5: 136.02697 | GL5: 136.72245 | GM5: 137.41793 | GN5: 138.11341 | GO5: 138.80889 | GP5: 139.50437 | GQ5: 140.19985 | GR5: 140.89533 | GS5: 141.59081 | GT5: 142.2863 | GU5: 142.98178 | GV5: 143.67726 | GW5: 144.37274 | GX5: 145.06822 | GY5: 145.7637 | GZ5: 146.45918 | HA5: 147.15466 | HB5: 147.85014 | HC5: 148.54562 | HD5: 149.2411
B6: Produits alimentaires | P6: 71.654748 | Q6: 71.594504 | R6: 71.928622 | S6: 72.451133 | T6: 73.014025 | U6: 73.023654 | V6: 73.205505 | W6: 74.065675 | X6: 74.235023 | Y6: 74.787488 | Z6: 74.315131 | AA6: 75.703499 | AB6: 75.250147 | AC6: 74.598381 | AD6: 74.635914 | AE6: 74.560515 | AF6: 75.00571 | AG6: 75.278209 | AH6: 75.279798 | AI6: 76.037498 | AJ6: 76.319646 | AK6: 77.124859 | AL6: 77.395328 | AM6: 77.409662 | AN6: 76.074792 | AO6: 75.926611 | AP6: 75.75988 | AQ6: 75.390703 | AR6: 76.074097 | AS6: 75.533847 | AT6: 76.568016 | AU6: 76.526957 | AV6: 76.566001 | AW6: 76.732752 | AX6: 77.179576 | AY6: 77.553858 | AZ6: 76.717649 | BA6: 76.785489 | BB6: 76.44619 | BC6: 77.280432 | BD6: 77.528807 | BE6: 77.721538 | BF6: 78.724906 | BG6: 78.168183 | BH6: 78.563007 | BI6: 79.122206 | BJ6: 78.410659 | BK6: 78.774923 | BL6: 78.08761 | BM6: 78.237569 | BN6: 78.062227 | BO6: 78.537744 | BP6: 79.492582 | BQ6: 78.925421 | BR6: 79.063304 | BS6: 79.210518 | BT6: 79.314405 | BU6: 78.632766 | BV6: 78.612406 | BW6: 78.292014 | BX6: 77.54055 | BY6: 77.632511 | BZ6: 77.558587 | CA6: 78.558748 | CB6: 78.788554 | CC6: 78.568117 | CD6: 78.740209 | CE6: 79.43623 | CF6: 79.730305 | CG6: 79.332144 | CH6: 79.300916 | CI6: 79.35899 | CJ6: 78.639512 | CK6: 78.639309 | CL6: 78.875885 | CM6: 79.505056 | CN6: 79.722991 | CO6: 79.367243 | CP6: 79.21043 | CQ6: 79.240901 | CR6: 79.989327 | CS6: 80.833913 | CT6: 80.928512 | CU6: 81.108503 | CV6: 80.195419 | CW6: 80.937306 | CX6: 81.270935 | CY6: 81.655628 | CZ6: 81.564554 | DA6: 81.83354 | DB6: 82.294196 | DC6: 82.269693 | DD6: 82.555577 | DE6: 82.781435 | DF6: 82.991728 | DG6: 83.305715 | DH6: 83.409855 | DI6: 83.538141 | DJ6: 84.12284 | DK6: 83.763573 | DL6: 84.01243 | DM6: 84.556049 | DN6: 85.673022 | DO6: 85.691929 | DP6: 85.66241 | DQ6: 86.212834 | DR6: 85.991852 | DS6: 86.244052 | DT6: 85.647729 | DU6: 85.891779 | DV6: 86.620803 | DW6: 87.210262 | DX6: 87.738987 | DY6: 88.445809 | DZ6: 89.527784 | EA6: 89.380198 | EB6: 89.545777 | EC6: 89.763417 | ED6: 90.067278 | EE6: 92.862379 | EF6: 93.465837 | EG6: 94.391775 | EH6: 95.288935 | EI6: 97.653476 | EJ6: 98.577093 | EK6: 99.156315 | EL6: 100.79542 | EM6: 102.44958 | EN6: 103.56584 | EO6: 103.82398 | EP6: 105.08337 | EQ6: 105.74839 | ER6: 106.7 | ES6: 107.3 | ET6: 107.6 | EU6: 108.9 | EV6: 110 | EW6: 111.2 | EX6: 112.2 | EY6: 113.6 | EZ6: 113.9 | FA6: 114.3 | FB6: 113.9 | FC6: 113.8 | FD6: 112.5 | FE6: 113.3 | FF6: 114.2 | FG6: 115.5 | FH6: 116 | FI6: 117 | FJ6: 117.1 | FK6: 118.3 | FL6: 120.7 | FM6: 121 | FN6: 120.6 | FO6: 122.3 | FP6: 121.6 | FQ6: 121.8 | FR6: 122.5
B7: Boissons non alcoolisées | P7: 81.573492 | Q7: 81.844686 | R7: 82.521435 | S7: 82.014033 | T7: 81.911215 | U7: 82.017064 | V7: 81.406434 | W7: 81.651618 | X7: 82.722631 | Y7: 82.603997 | Z7: 82.930729 | AA7: 82.841909 | AB7: 83.835541 | AC7: 83.990396 | AD7: 83.887495 | AE7: 83.886782 | AF7: 84.430309 | AG7: 84.119248 | AH7: 83.664553 | AI7: 83.448731 | AJ7: 83.258803 | AK7: 83.68711 | AL7: 83.218081 | AM7: 83.302582 | AN7: 83.451537 | AO7: 83.537463 | AP7: 83.614804 | AQ7: 83.835412 | AR7: 83.562997 | AS7: 83.264737 | AT7: 83.977165 | AU7: 84.435642 | AV7: 84.383423 | AW7: 84.329212 | AX7: 84.572493 | AY7: 84.339205 | AZ7: 84.539841 | BA7: 85.141368 | BB7: 86.640329 | BC7: 86.931294 | BD7: 87.040483 | BE7: 87.549333 | BF7: 87.636204 | BG7: 87.536465 | BH7: 87.837797 | BI7: 87.640906 | BJ7: 87.403143 | BK7: 87.497766 | BL7: 87.590502 | BM7: 87.913126 | BN7: 87.667914 | BO7: 86.993105 | BP7: 87.078903 | BQ7: 87.14873 | BR7: 87.060377 | BS7: 87.295922 | BT7: 87.260956 | BU7: 87.45085 | BV7: 87.275678 | BW7: 87.395493 | BX7: 87.948341 | BY7: 87.840699 | BZ7: 87.48724 | CA7: 87.814787 | CB7: 87.622816 | CC7: 87.581933 | CD7: 87.95611 | CE7: 87.845835 | CF7: 87.768659 | CG7: 87.66506 | CH7: 87.657426 | CI7: 87.827684 | CJ7: 87.959817 | CK7: 87.884245 | CL7: 87.916056 | CM7: 88.282095 | CN7: 88.60103 | CO7: 88.632984 | CP7: 88.525744 | CQ7: 88.515414 | CR7: 88.972132 | CS7: 89.15298 | CT7: 89.315001 | CU7: 89.499182 | CV7: 89.435816 | CW7: 89.638224 | CX7: 91.283811 | CY7: 91.806139 | CZ7: 91.770149 | DA7: 91.830233 | DB7: 91.809347 | DC7: 92.150592 | DD7: 92.23163 | DE7: 93.165165 | DF7: 92.987394 | DG7: 93.477523 | DH7: 93.369887 | DI7: 93.345982 | DJ7: 93.487342 | DK7: 93.622139 | DL7: 93.877324 | DM7: 93.955065 | DN7: 93.985108 | DO7: 94.26374 | DP7: 94.880596 | DQ7: 95.023899 | DR7: 94.914273 | DS7: 95.003151 | DT7: 95.065061 | DU7: 95.15203 | DV7: 95.243816 | DW7: 95.392969 | DX7: 95.441199 | DY7: 95.769925 | DZ7: 96.071734 | EA7: 96.348181 | EB7: 96.563492 | EC7: 96.579053 | ED7: 96.723987 | EE7: 97.340892 | EF7: 97.455153 | EG7: 98.252151 | EH7: 98.909988 | EI7: 99.185687 | EJ7: 99.648178 | EK7: 99.8377 | EL7: 100.31601 | EM7: 100.91955 | EN7: 100.9916 | EO7: 101.02734 | EP7: 101.46796 | EQ7: 101.98868 | ER7: 101.9 | ES7: 102.3 | ET7: 102.5 | EU7: 102.7 | EV7: 102.7 | EW7: 102.8 | EX7: 102.9 | EY7: 103 | EZ7: 103.1 | FA7: 103.1 | FB7: 103.1 | FC7: 103.1 | FD7: 103.4 | FE7: 103.5 | FF7: 103.6 | FG7: 103.7 | FH7: 103.8 | FI7: 104 | FJ7: 104 | FK7: 104 | FL7: 104.1 | FM7: 104.2 | FN7: 104.3 | FO7: 104.3 | FP7: 104.6 | FQ7: 104.7 | FR7: 105
A8: 02 | B8: Boissons alcoolisées et tabac | C8: 1.36 | P8: 71.228778 | Q8: 71.876501 | R8: 72.438837 | S8: 72.371557 | T8: 72.588637 | U8: 72.224466 | V8: 72.073768 | W8: 72.152977 | X8: 72.692644 | Y8: 72.277543 | Z8: 72.76464 | AA8: 72.772231 | AB8: 72.984789 | AC8: 73.166762 | AD8: 73.215128 | AE8: 74.464933 | AF8: 74.554433 | AG8: 74.617245 | AH8: 75.076854 | AI8: 74.87038 | AJ8: 74.778547 | AK8: 75.149681 | AL8: 75.291804 | AM8: 75.377602 | AN8: 75.289929 | AO8: 74.998289 | AP8: 75.33071 | AQ8: 75.418327 | AR8: 75.646485 | AS8: 75.3803 | AT8: 75.186846 | AU8: 75.73604 | AV8: 75.345208 | AW8: 75.83627 | AX8: 75.652585 | AY8: 76.068652 | AZ8: 75.826024 | BA8: 79.550209 | BB8: 81.555893 | BC8: 82.698856 | BD8: 82.999504 | BE8: 82.955882 | BF8: 83.04248 | BG8: 83.060421 | BH8: 83.044767 | BI8: 83.978342 | BJ8: 83.998233 | BK8: 84.167573 | BL8: 84.508601 | BM8: 84.268919 | BN8: 84.471671 | BO8: 84.537472 | BP8: 84.937549 | BQ8: 84.89251 | BR8: 84.774896 | BS8: 84.487003 | BT8: 84.886432 | BU8: 84.448254 | BV8: 85.143871 | BW8: 85.111616 | BX8: 85.640218 | BY8: 85.59113 | BZ8: 86.253682 | CA8: 85.625453 | CB8: 85.579484 | CC8: 85.683018 | CD8: 85.967457 | CE8: 86.050916 | CF8: 85.897762 | CG8: 86.293036 | CH8: 86.208875 | CI8: 86.237234 | CJ8: 86.566556 | CK8: 86.222404 | CL8: 86.106834 | CM8: 86.583849 | CN8: 86.733826 | CO8: 87.066894 | CP8: 87.394272 | CQ8: 87.497917 | CR8: 87.9113 | CS8: 88.022933 | CT8: 87.954462 | CU8: 88.13535 | CV8: 88.55422 | CW8: 89.371198 | CX8: 90.056492 | CY8: 91.184147 | CZ8: 91.647792 | DA8: 91.808182 | DB8: 91.837148 | DC8: 92.007246 | DD8: 92.075644 | DE8: 92.232385 | DF8: 92.369569 | DG8: 92.664005 | DH8: 93.42294 | DI8: 93.435118 | DJ8: 93.290022 | DK8: 93.511523 | DL8: 93.68319 | DM8: 93.856819 | DN8: 93.949079 | DO8: 94.136024 | DP8: 94.232782 | DQ8: 94.806248 | DR8: 95.279878 | DS8: 95.375957 | DT8: 95.106415 | DU8: 95.182 | DV8: 95.157453 | DW8: 95.535316 | DX8: 95.602766 | DY8: 95.891909 | DZ8: 96.114636 | EA8: 96.027549 | EB8: 96.320005 | EC8: 97.158007 | ED8: 96.87616 | EE8: 97.444282 | EF8: 98.338146 | EG8: 98.330232 | EH8: 98.423841 | EI8: 98.923589 | EJ8: 99.334323 | EK8: 99.825103 | EL8: 100.34996 | EM8: 100.7303 | EN8: 100.90681 | EO8: 101.27702 | EP8: 101.89516 | EQ8: 101.66553 | ER8: 101.65993 | ES8: 101.8663 | ET8: 102.15936 | EU8: 103.5612 | EV8: 103.67914 | EW8: 103.80892 | EX8: 103.90078 | EY8: 104.0703 | EZ8: 104.04734 | FA8: 104.05113 | FB8: 103.9706 | FC8: 104.07542 | FD8: 104.3 | FE8: 104.8 | FF8: 105 | FG8: 105.6 | FH8: 106 | FI8: 105.9 | FJ8: 106.07448 | FK8: 106.1211 | FL8: 106.24319 | FM8: 106.20609 | FN8: 107.07399 | FO8: 107.58681 | FP8: 108 | FQ8: 108.9 | FR8: 109.4 | FS8: 109.00984 | FT8: 109.32876 | FU8: 109.64769 | FV8: 109.96661 | FW8: 110.28554 | FX8: 110.60446 | FY8: 110.92339 | FZ8: 111.24231 | GA8: 111.56124 | GB8: 111.88016 | GC8: 112.19909 | GD8: 112.51802 | GE8: 112.83694 | GF8: 113.15587 | GG8: 113.47479 | GH8: 113.79372 | GI8: 114.11264 | GJ8: 114.43157 | GK8: 114.75049 | GL8: 115.06942 | GM8: 115.38834 | GN8: 115.70727 | GO8: 116.02619 | GP8: 116.34512 | GQ8: 116.66405 | GR8: 116.98297 | GS8: 117.3019 | GT8: 117.62082 | GU8: 117.93975 | GV8: 118.25867 | GW8: 118.5776 | GX8: 118.89652 | GY8: 119.21545 | GZ8: 119.53437 | HA8: 119.8533 | HB8: 120.17223 | HC8: 120.49115 | HD8: 120.81008
A9: 03 | B9: Articles d'habillement et chaussures | C9: 9.84 | P9: 83.476174 | Q9: 83.947549 | R9: 83.996334 | S9: 83.857415 | T9: 84.247667 | U9: 84.512491 | V9: 84.742456 | W9: 84.631754 | X9: 84.073737 | Y9: 84.523316 | Z9: 84.21387 | AA9: 85.809254 | AB9: 84.833629 | AC9: 85.122031 | AD9: 84.927872 | AE9: 85.229255 | AF9: 84.983532 | AG9: 85.196981 | AH9: 85.190923 | AI9: 85.478654 | AJ9: 85.571516 | AK9: 85.792152 | AL9: 85.613966 | AM9: 86.918045 | AN9: 86.090258 | AO9: 86.115388 | AP9: 85.756054 | AQ9: 86.048011 | AR9: 86.62486 | AS9: 86.790887 | AT9: 87.070468 | AU9: 86.953191 | AV9: 86.772742 | AW9: 87.082706 | AX9: 87.300904 | AY9: 88.191733 | AZ9: 87.102824 | BA9: 86.980531 | BB9: 86.954252 | BC9: 86.328772 | BD9: 86.775466 | BE9: 87.117308 | BF9: 86.978537 | BG9: 86.972634 | BH9: 86.775554 | BI9: 86.437629 | BJ9: 86.667536 | BK9: 87.403896 | BL9: 86.729732 | BM9: 86.614618 | BN9: 86.731218 | BO9: 86.34895 | BP9: 86.442557 | BQ9: 86.638933 | BR9: 87.17763 | BS9: 87.285229 | BT9: 87.302991 | BU9: 87.192224 | BV9: 86.714196 | BW9: 88.054324 | BX9: 87.758405 | BY9: 87.552877 | BZ9: 87.609637 | CA9: 87.667743 | CB9: 87.553472 | CC9: 87.609326 | CD9: 87.714665 | CE9: 87.844777 | CF9: 87.972465 | CG9: 87.789979 | CH9: 87.871525 | CI9: 88.279084 | CJ9: 88.29027 | CK9: 88.6123 | CL9: 88.647802 | CM9: 88.951036 | CN9: 89.167714 | CO9: 89.242393 | CP9: 89.406535 | CQ9: 89.596819 | CR9: 89.761456 | CS9: 90.14052 | CT9: 90.444038 | CU9: 90.876477 | CV9: 90.79528 | CW9: 90.931962 | CX9: 91.100082 | CY9: 91.409581 | CZ9: 91.596731 | DA9: 91.910503 | DB9: 92.029266 | DC9: 92.169215 | DD9: 92.285255 | DE9: 92.776551 | DF9: 93.097174 | DG9: 93.494535 | DH9: 93.220763 | DI9: 93.355324 | DJ9: 93.263147 | DK9: 93.740229 | DL9: 93.925802 | DM9: 94.168846 | DN9: 94.160123 | DO9: 94.255885 | DP9: 94.60134 | DQ9: 94.741428 | DR9: 94.842953 | DS9: 95.179006 | DT9: 95.2234 | DU9: 95.288445 | DV9: 95.77351 | DW9: 95.625559 | DX9: 95.811464 | DY9: 96.0336 | DZ9: 96.386904 | EA9: 96.551642 | EB9: 96.414601 | EC9: 96.867312 | ED9: 97.042492 | EE9: 97.301393 | EF9: 97.66954 | EG9: 98.206663 | EH9: 98.502684 | EI9: 99.398581 | EJ9: 99.893436 | EK9: 100.48973 | EL9: 100.08378 | EM9: 100.45318 | EN9: 101.03582 | EO9: 101.23341 | EP9: 101.26261 | EQ9: 101.77057 | ER9: 102.07135 | ES9: 102.58649 | ET9: 102.98421 | EU9: 104.12362 | EV9: 104.14809 | EW9: 104.37752 | EX9: 104.60186 | EY9: 105.00355 | EZ9: 105.20533 | FA9: 105.26384 | FB9: 105.43501 | FC9: 106.32147 | FD9: 106.1 | FE9: 106.3 | FF9: 106.6 | FG9: 106.6 | FH9: 106.7 | FI9: 106.7 | FJ9: 106.85034 | FK9: 106.9197 | FL9: 107.11904 | FM9: 107.26185 | FN9: 107.64424 | FO9: 108.73713 | FP9: 108.5 | FQ9: 108.7 | FR9: 108.8 | FS9: 108.96946 | FT9: 109.18342 | FU9: 109.39739 | FV9: 109.61135 | FW9: 109.82531 | FX9: 110.03928 | FY9: 110.25324 | FZ9: 110.4672 | GA9: 110.68117 | GB9: 110.89513 | GC9: 111.10909 | GD9: 111.32306 | GE9: 111.53702 | GF9: 111.75098 | GG9: 111.96495 | GH9: 112.17891 | GI9: 112.39287 | GJ9: 112.60684 | GK9: 112.8208 | GL9: 113.03476 | GM9: 113.24873 | GN9: 113.46269 | GO9: 113.67665 | GP9: 113.89062 | GQ9: 114.10458 | GR9: 114.31855 | GS9: 114.53251 | GT9: 114.74647 | GU9: 114.96044 | GV9: 115.1744 | GW9: 115.38836 | GX9: 115.60233 | GY9: 115.81629 | GZ9: 116.03025 | HA9: 116.24422 | HB9: 116.45818 | HC9: 116.67214 | HD9: 116.88611
A10: 04 | B10: Logement, eau, gaz, électricité et autres combustibles | C10: 12.89 | P10: 81.608481 | Q10: 81.145336 | R10: 82.20782 | S10: 82.451968 | T10: 82.418772 | U10: 83.346177 | V10: 83.457488 | W10: 83.360419 | X10: 82.800046 | Y10: 83.364315 | Z10: 83.504596 | AA10: 83.826556 | AB10: 84.129725 | AC10: 84.121631 | AD10: 84.959719 | AE10: 84.313233 | AF10: 84.223368 | AG10: 84.624939 | AH10: 85.187088 | AI10: 84.768745 | AJ10: 85.780529 | AK10: 86.169335 | AL10: 86.34061 | AM10: 86.218288 | AN10: 86.587925 | AO10: 86.651411 | AP10: 86.61145 | AQ10: 85.829228 | AR10: 85.465822 | AS10: 85.249266 | AT10: 86.304396 | AU10: 86.627533 | AV10: 87.415433 | AW10: 86.925009 | AX10: 88.70872 | AY10: 88.927278 | AZ10: 87.846742 | BA10: 88.647994 | BB10: 88.285375 | BC10: 88.990435 | BD10: 88.800845 | BE10: 89.968131 | BF10: 89.819531 | BG10: 89.820728 | BH10: 90.189772 | BI10: 89.241311 | BJ10: 89.835429 | BK10: 90.399461 | BL10: 90.11378 | BM10: 89.492509 | BN10: 90.540951 | BO10: 90.425752 | BP10: 91.062887 | BQ10: 90.24052 | BR10: 90.27982 | BS10: 91.234496 | BT10: 90.668774 | BU10: 90.904027 | BV10: 90.783048 | BW10: 91.515639 | BX10: 90.878327 | BY10: 90.950208 | BZ10: 91.600416 | CA10: 91.561676 | CB10: 91.577064 | CC10: 91.755206 | CD10: 91.659982 | CE10: 91.834272 | CF10: 92.046879 | CG10: 92.473355 | CH10: 92.211332 | CI10: 91.650866 | CJ10: 92.283948 | CK10: 91.60002 | CL10: 91.173711 | CM10: 91.551006 | CN10: 91.838205 | CO10: 92.129283 | CP10: 91.863562 | CQ10: 92.006945 | CR10: 92.120429 | CS10: 92.685009 | CT10: 92.715955 | CU10: 92.679197 | CV10: 92.803115 | CW10: 92.430523 | CX10: 92.875504 | CY10: 92.73042 | CZ10: 92.618579 | DA10: 92.583228 | DB10: 92.886596 | DC10: 93.664809 | DD10: 93.730177 | DE10: 95.058129 | DF10: 96.132511 | DG10: 95.590136 | DH10: 95.998231 | DI10: 95.988122 | DJ10: 96.15084 | DK10: 96.266169 | DL10: 96.816422 | DM10: 95.960713 | DN10: 95.967131 | DO10: 96.847619 | DP10: 95.933188 | DQ10: 97.101632 | DR10: 96.858526 | DS10: 97.161562 | DT10: 97.686113 | DU10: 97.591938 | DV10: 97.532431 | DW10: 98.008676 | DX10: 98.344716 | DY10: 98.312183 | DZ10: 98.651659 | EA10: 98.242806 | EB10: 98.483058 | EC10: 98.502104 | ED10: 98.22765 | EE10: 98.552558 | EF10: 99.167533 | EG10: 99.005432 | EH10: 99.756799 | EI10: 99.849233 | EJ10: 100.15214 | EK10: 99.4167 | EL10: 99.347191 | EM10: 99.695295 | EN10: 99.822266 | EO10: 101.00185 | EP10: 101.16489 | EQ10: 101.62067 | ER10: 101.69286 | ES10: 102.38159 | ET10: 102.59518 | EU10: 102.74684 | EV10: 103.06456 | EW10: 103.36919 | EX10: 103.94054 | EY10: 103.83783 | EZ10: 103.99272 | FA10: 104.22801 | FB10: 104.71919 | FC10: 104.47789 | FD10: 104.7 | FE10: 105.6 | FF10: 105.7 | FG10: 105.9 | FH10: 106.7 | FI10: 107.1 | FJ10: 107.05955 | FK10: 107.29182 | FL10: 107.51894 | FM10: 107.66366 | FN10: 108.01433 | FO10: 108.4781 | FP10: 108.7 | FQ10: 108.7 | FR10: 109.1 | FS10: 109.41033 | FT10: 109.67854 | FU10: 109.94676 | FV10: 110.21498 | FW10: 110.4832 | FX10: 110.75142 | FY10: 111.01963 | FZ10: 111.28785 | GA10: 111.55607 | GB10: 111.82429 | GC10: 112.09251 | GD10: 112.36073 | GE10: 112.62894 | GF10: 112.89716 | GG10: 113.16538 | GH10: 113.4336 | GI10: 113.70182 | GJ10: 113.97003 | GK10: 114.23825 | GL10: 114.50647 | GM10: 114.77469 | GN10: 115.04291 | GO10: 115.31112 | GP10: 115.57934 | GQ10: 115.84756 | GR10: 116.11578 | GS10: 116.384 | GT10: 116.65221 | GU10: 116.92043 | GV10: 117.18865 | GW10: 117.45687 | GX10: 117.72509 | GY10: 117.99331 | GZ10: 118.26152 | HA10: 118.52974 | HB10: 118.79796 | HC10: 119.06618 | HD10: 119.3344
A11: 05 | B11: Meubles, articles de ménage et entretien courant de la maison | C11: 5.1 | P11: 85.477666 | Q11: 85.140194 | R11: 85.218789 | S11: 85.370018 | T11: 85.38013 | U11: 84.609568 | V11: 85.17722 | W11: 84.962662 | X11: 84.97514 | Y11: 85.299743 | Z11: 85.441104 | AA11: 85.69565 | AB11: 86.239608 | AC11: 86.972958 | AD11: 86.728536 | AE11: 86.468399 | AF11: 86.907173 | AG11: 86.656741 | AH11: 87.213544 | AI11: 87.269271 | AJ11: 87.426758 | AK11: 87.251358 | AL11: 87.253563 | AM11: 87.572937 | AN11: 87.11149 | AO11: 87.409817 | AP11: 87.086627 | AQ11: 87.073402 | AR11: 87.100025 | AS11: 87.074313 | AT11: 87.376936 | AU11: 87.653297 | AV11: 87.809453 | AW11: 87.293969 | AX11: 87.528741 | AY11: 87.533063 | AZ11: 87.733019 | BA11: 88.089201 | BB11: 87.986009 | BC11: 88.492966 | BD11: 88.464932 | BE11: 88.676096 | BF11: 89.080592 | BG11: 88.868803 | BH11: 89.209255 | BI11: 88.930053 | BJ11: 88.891154 | BK11: 88.907343 | BL11: 88.831955 | BM11: 88.874844 | BN11: 89.598053 | BO11: 89.29167 | BP11: 89.113587 | BQ11: 88.98499 | BR11: 88.748873 | BS11: 88.97586 | BT11: 89.071836 | BU11: 89.43469 | BV11: 89.470831 | BW11: 89.628991 | BX11: 89.639242 | BY11: 89.295619 | BZ11: 89.477441 | CA11: 89.315764 | CB11: 89.1405 | CC11: 89.240818 | CD11: 89.405942 | CE11: 89.462198 | CF11: 89.443898 | CG11: 89.515758 | CH11: 89.497028 | CI11: 89.799555 | CJ11: 89.517859 | CK11: 89.65842 | CL11: 89.640687 | CM11: 89.922716 | CN11: 90.111723 | CO11: 90.226868 | CP11: 90.227913 | CQ11: 90.339526 | CR11: 90.641411 | CS11: 90.788739 | CT11: 90.739928 | CU11: 90.991109 | CV11: 91.15132 | CW11: 91.380856 | CX11: 91.51321 | CY11: 91.825366 | CZ11: 91.95076 | DA11: 91.940317 | DB11: 91.949488 | DC11: 92.054692 | DD11: 92.163033 | DE11: 92.300152 | DF11: 92.377793 | DG11: 92.53858 | DH11: 92.64357 | DI11: 92.582435 | DJ11: 92.632931 | DK11: 92.783999 | DL11: 93.163051 | DM11: 93.452155 | DN11: 93.357434 | DO11: 93.462253 | DP11: 93.77837 | DQ11: 94.028958 | DR11: 94.08246 | DS11: 94.070557 | DT11: 94.177626 | DU11: 94.319608 | DV11: 94.452889 | DW11: 94.457674 | DX11: 94.502592 | DY11: 94.568668 | DZ11: 94.722046 | EA11: 94.772989 | EB11: 94.818019 | EC11: 94.940378 | ED11: 95.060604 | EE11: 95.136269 | EF11: 95.421829 | EG11: 96.167584 | EH11: 96.903031 | EI11: 97.922948 | EJ11: 98.86533 | EK11: 99.78915 | EL11: 100.80535 | EM11: 101.26254 | EN11: 101.98702 | EO11: 102.70313 | EP11: 103.74248 | EQ11: 104.4296 | ER11: 105.23528 | ES11: 105.74341 | ET11: 106.34148 | EU11: 107.04328 | EV11: 107.27779 | EW11: 107.46936 | EX11: 107.53873 | EY11: 107.62349 | EZ11: 107.72931 | FA11: 107.919 | FB11: 108.06678 | FC11: 108.15354 | FD11: 108.2 | FE11: 108.6 | FF11: 108.7 | FG11: 108.9 | FH11: 109.2 | FI11: 109.4 | FJ11: 109.58834 | FK11: 109.74043 | FL11: 109.81538 | FM11: 109.84 | FN11: 109.88183 | FO11: 109.67039 | FP11: 110 | FQ11: 110.1 | FR11: 110.2 | FS11: 110.37579 | FT11: 110.48402 | FU11: 110.59225 | FV11: 110.70047 | FW11: 110.8087 | FX11: 110.91693 | FY11: 111.02516 | FZ11: 111.13339 | GA11: 111.24162 | GB11: 111.34985 | GC11: 111.45808 | GD11: 111.56631 | GE11: 111.67454 | GF11: 111.78277 | GG11: 111.891 | GH11: 111.99923 | GI11: 112.10745 | GJ11: 112.21568 | GK11: 112.32391 | GL11: 112.43214 | GM11: 112.54037 | GN11: 112.6486 | GO11: 112.75683 | GP11: 112.86506 | GQ11: 112.97329 | GR11: 113.08152 | GS11: 113.18975 | GT11: 113.29798 | GU11: 113.40621 | GV11: 113.51443 | GW11: 113.62266 | GX11: 113.73089 | GY11: 113.83912 | GZ11: 113.94735 | HA11: 114.05558 | HB11: 114.16381 | HC11: 114.27204 | HD11: 114.38027
A12: 06 | B12: Santé | C12: 4.78 | P12: 96.282748 | Q12: 96.580758 | R12: 96.757232 | S12: 96.56153 | T12: 96.377764 | U12: 96.203801 | V12: 96.503132 | W12: 96.641388 | X12: 96.646281 | Y12: 96.474663 | Z12: 96.470429 | AA12: 96.572134 | AB12: 96.534001 | AC12: 96.836536 | AD12: 96.863765 | AE12: 96.8666 | AF12: 96.902408 | AG12: 97.091207 | AH12: 96.902505 | AI12: 96.70861 | AJ12: 96.861221 | AK12: 97.678173 | AL12: 97.725536 | AM12: 97.503508 | AN12: 97.744686 | AO12: 97.638657 | AP12: 97.735972 | AQ12: 97.617366 | AR12: 97.856002 | AS12: 97.681431 | AT12: 97.853825 | AU12: 97.885985 | AV12: 97.767296 | AW12: 97.836935 | AX12: 97.763687 | AY12: 97.686248 | AZ12: 98.170032 | BA12: 98.136498 | BB12: 98.373504 | BC12: 98.509167 | BD12: 98.070677 | BE12: 98.158355 | BF12: 97.953376 | BG12: 98.014158 | BH12: 98.049281 | BI12: 98.570129 | BJ12: 98.425948 | BK12: 98.211573 | BL12: 98.056453 | BM12: 97.941023 | BN12: 97.917432 | BO12: 98.140997 | BP12: 97.778613 | BQ12: 97.687706 | BR12: 97.756741 | BS12: 97.702589 | BT12: 97.798971 | BU12: 97.936906 | BV12: 98.068263 | BW12: 98.153903 | BX12: 98.206815 | BY12: 98.204638 | BZ12: 97.946729 | CA12: 98.141302 | CB12: 98.1926 | CC12: 98.206248 | CD12: 98.240516 | CE12: 98.210266 | CF12: 98.21459 | CG12: 98.286994 | CH12: 98.299421 | CI12: 98.316978 | CJ12: 98.194292 | CK12: 98.229916 | CL12: 98.23695 | CM12: 98.366581 | CN12: 98.544798 | CO12: 98.63713 | CP12: 98.910456 | CQ12: 98.91951 | CR12: 98.920384 | CS12: 98.927395 | CT12: 98.921205 | CU12: 98.930274 | CV12: 98.918227 | CW12: 98.978593 | CX12: 99.131724 | CY12: 99.196066 | CZ12: 99.227934 | DA12: 99.253974 | DB12: 99.315514 | DC12: 99.242231 | DD12: 99.258826 | DE12: 99.268226 | DF12: 99.277015 | DG12: 99.292124 | DH12: 99.254991 | DI12: 99.282654 | DJ12: 99.334038 | DK12: 99.372313 | DL12: 99.430866 | DM12: 99.453132 | DN12: 99.396361 | DO12: 99.409634 | DP12: 99.49852 | DQ12: 99.541922 | DR12: 99.533434 | DS12: 99.528246 | DT12: 99.514029 | DU12: 99.516777 | DV12: 99.521965 | DW12: 99.495826 | DX12: 99.544655 | DY12: 99.548251 | DZ12: 99.591688 | EA12: 99.588963 | EB12: 99.624608 | EC12: 99.640489 | ED12: 99.661599 | EE12: 99.667083 | EF12: 99.707061 | EG12: 99.6829 | EH12: 99.815952 | EI12: 99.932093 | EJ12: 99.892449 | EK12: 100.02307 | EL12: 100.05505 | EM12: 100.06269 | EN12: 100.10484 | EO12: 100.16261 | EP12: 100.26991 | EQ12: 100.29138 | ER12: 100.46392 | ES12: 100.62069 | ET12: 100.69337 | EU12: 100.79603 | EV12: 100.82795 | EW12: 100.84413 | EX12: 100.89654 | EY12: 100.9654 | EZ12: 100.9901 | FA12: 101.01048 | FB12: 101.03592 | FC12: 101.04787 | FD12: 101.1 | FE12: 101.2 | FF12: 101.4 | FG12: 101.4 | FH12: 101.4 | FI12: 101.5 | FJ12: 101.5395 | FK12: 101.53068 | FL12: 101.62688 | FM12: 101.67131 | FN12: 101.72856 | FO12: 101.80681 | FP12: 101.8 | FQ12: 101.9 | FR12: 101.9 | FS12: 101.95949 | FT12: 102.00641 | FU12: 102.05332 | FV12: 102.10024 | FW12: 102.14716 | FX12: 102.19408 | FY12: 102.241 | FZ12: 102.28792 | GA12: 102.33484 | GB12: 102.38176 | GC12: 102.42867 | GD12: 102.47559 | GE12: 102.52251 | GF12: 102.56943 | GG12: 102.61635 | GH12: 102.66327 | GI12: 102.71019 | GJ12: 102.75711 | GK12: 102.80402 | GL12: 102.85094 | GM12: 102.89786 | GN12: 102.94478 | GO12: 102.9917 | GP12: 103.03862 | GQ12: 103.08554 | GR12: 103.13245 | GS12: 103.17937 | GT12: 103.22629 | GU12: 103.27321 | GV12: 103.32013 | GW12: 103.36705 | GX12: 103.41397 | GY12: 103.46089 | GZ12: 103.5078 | HA12: 103.55472 | HB12: 103.60164 | HC12: 103.64856 | HD12: 103.69548
A13: 07 | B13: Transports | C13: 11.27 | P13: 77.104881 | Q13: 76.889758 | R13: 76.841601 | S13: 77.257096 | T13: 77.523434 | U13: 77.557357 | V13: 78.793887 | W13: 79.039137 | X13: 79.033503 | Y13: 78.977382 | Z13: 79.123393 | AA13: 79.404572 | AB13: 79.132305 | AC13: 79.379034 | AD13: 79.180723 | AE13: 79.524185 | AF13: 79.403262 | AG13: 79.549257 | AH13: 79.400788 | AI13: 79.897551 | AJ13: 79.749655 | AK13: 80.06884 | AL13: 79.702207 | AM13: 80.195502 | AN13: 80.401441 | AO13: 80.270643 | AP13: 80.0292 | AQ13: 79.944569 | AR13: 80.299669 | AS13: 80.511459 | AT13: 90.627178 | AU13: 90.96381 | AV13: 91.504831 | AW13: 91.056197 | AX13: 91.670599 | AY13: 91.605353 | AZ13: 91.780704 | BA13: 91.930349 | BB13: 92.132538 | BC13: 92.009186 | BD13: 92.354255 | BE13: 92.436864 | BF13: 91.955704 | BG13: 92.444255 | BH13: 92.591751 | BI13: 92.159589 | BJ13: 92.256901 | BK13: 92.205914 | BL13: 91.327392 | BM13: 91.139876 | BN13: 91.646022 | BO13: 91.389195 | BP13: 91.574054 | BQ13: 91.672232 | BR13: 91.414358 | BS13: 91.897138 | BT13: 91.476334 | BU13: 91.573205 | BV13: 91.634124 | BW13: 91.711489 | BX13: 92.145201 | BY13: 92.13738 | BZ13: 92.339513 | CA13: 92.429541 | CB13: 92.3582 | CC13: 92.380234 | CD13: 92.174018 | CE13: 92.409065 | CF13: 92.305394 | CG13: 92.058969 | CH13: 92.084827 | CI13: 92.258462 | CJ13: 92.153418 | CK13: 92.22789 | CL13: 92.140669 | CM13: 92.236743 | CN13: 92.305703 | CO13: 92.440538 | CP13: 93.135747 | CQ13: 93.400513 | CR13: 93.398843 | CS13: 93.596986 | CT13: 93.66378 | CU13: 93.976653 | CV13: 94.125321 | CW13: 94.147607 | CX13: 94.192631 | CY13: 94.550636 | CZ13: 94.663221 | DA13: 94.659552 | DB13: 94.723591 | DC13: 94.89459 | DD13: 94.894545 | DE13: 94.987907 | DF13: 95.029869 | DG13: 95.340784 | DH13: 95.133617 | DI13: 95.462764 | DJ13: 96.208337 | DK13: 99.988453 | DL13: 96.358909 | DM13: 96.295893 | DN13: 96.270915 | DO13: 96.387555 | DP13: 96.510405 | DQ13: 96.783672 | DR13: 96.886308 | DS13: 96.930766 | DT13: 96.851005 | DU13: 96.836477 | DV13: 96.932997 | DW13: 97.005928 | DX13: 97.096782 | DY13: 97.137169 | DZ13: 97.497267 | EA13: 97.584626 | EB13: 97.560297 | EC13: 97.807655 | ED13: 97.949423 | EE13: 98.396289 | EF13: 98.616543 | EG13: 98.779089 | EH13: 99.040255 | EI13: 99.309691 | EJ13: 99.513094 | EK13: 100.34314 | EL13: 100.31145 | EM13: 100.71072 | EN13: 100.70004 | EO13: 100.85272 | EP13: 100.89328 | EQ13: 100.92999 | ER13: 101.05273 | ES13: 109.69452 | ET13: 114.85975 | EU13: 115.2817 | EV13: 115.63748 | EW13: 117.09953 | EX13: 117.38806 | EY13: 117.5824 | EZ13: 117.54189 | FA13: 117.5239 | FB13: 117.93591 | FC13: 118.48707 | FD13: 118.2 | FE13: 125.8 | FF13: 128.3 | FG13: 129.6 | FH13: 130.2 | FI13: 130.2 | FJ13: 130.23352 | FK13: 130.1636 | FL13: 130.68177 | FM13: 131.5441 | FN13: 131.97174 | FO13: 132.16938 | FP13: 131.8 | FQ13: 131.8 | FR13: 131.9 | FS13: 132.72666 | FT13: 133.0001 | FU13: 133.27353 | FV13: 133.54697 | FW13: 133.8204 | FX13: 134.09384 | FY13: 134.36727 | FZ13: 134.64071 | GA13: 134.91414 | GB13: 135.18757 | GC13: 135.46101 | GD13: 135.73444 | GE13: 136.00788 | GF13: 136.28131 | GG13: 136.55475 | GH13: 136.82818 | GI13: 137.10162 | GJ13: 137.37505 | GK13: 137.64848 | GL13: 137.92192 | GM13: 138.19535 | GN13: 138.46879 | GO13: 138.74222 | GP13: 139.01566 | GQ13: 139.28909 | GR13: 139.56253 | GS13: 139.83596 | GT13: 140.10939 | GU13: 140.38283 | GV13: 140.65626 | GW13: 140.9297 | GX13: 141.20313 | GY13: 141.47657 | GZ13: 141.75 | HA13: 142.02344 | HB13: 142.29687 | HC13: 142.5703 | HD13: 142.84374
A14: 08 | B14: Communications | C14: 4.59 | P14: 109.05164 | Q14: 108.13911 | R14: 108.62168 | S14: 108.49477 | T14: 108.75607 | U14: 108.10319 | V14: 107.30394 | W14: 106.72664 | X14: 107.10509 | Y14: 106.76614 | Z14: 106.89185 | AA14: 106.54722 | AB14: 106.12678 | AC14: 105.53068 | AD14: 105.56934 | AE14: 106.65271 | AF14: 105.36851 | AG14: 104.54903 | AH14: 104.01243 | AI14: 103.40017 | AJ14: 103.41954 | AK14: 103.52534 | AL14: 103.42388 | AM14: 103.49918 | AN14: 103.34755 | AO14: 102.52898 | AP14: 103.08007 | AQ14: 102.19498 | AR14: 102.04587 | AS14: 102.88875 | AT14: 102.45728 | AU14: 100.7277 | AV14: 101.72641 | AW14: 101.01331 | AX14: 101.24286 | AY14: 100.56202 | AZ14: 99.978959 | BA14: 99.641745 | BB14: 99.763791 | BC14: 99.665555 | BD14: 99.652308 | BE14: 100.90771 | BF14: 99.435946 | BG14: 99.829678 | BH14: 98.398445 | BI14: 98.102533 | BJ14: 97.412554 | BK14: 97.631755 | BL14: 98.320521 | BM14: 98.235143 | BN14: 97.150836 | BO14: 96.789757 | BP14: 96.525153 | BQ14: 96.776297 | BR14: 96.507909 | BS14: 96.614629 | BT14: 96.527436 | BU14: 96.322824 | BV14: 97.135173 | BW14: 97.131657 | BX14: 97.851736 | BY14: 97.328028 | BZ14: 97.69548 | CA14: 97.945047 | CB14: 97.642732 | CC14: 97.649226 | CD14: 97.686156 | CE14: 97.749781 | CF14: 97.662998 | CG14: 97.715878 | CH14: 97.557534 | CI14: 97.61447 | CJ14: 97.717456 | CK14: 97.606064 | CL14: 98.018145 | CM14: 97.952431 | CN14: 97.946786 | CO14: 97.84579 | CP14: 97.882521 | CQ14: 97.912654 | CR14: 97.927955 | CS14: 97.926346 | CT14: 97.995375 | CU14: 98.018552 | CV14: 97.909897 | CW14: 97.969753 | CX14: 98.009302 | CY14: 98.043292 | CZ14: 98.15258 | DA14: 98.169895 | DB14: 98.115261 | DC14: 98.124008 | DD14: 98.198437 | DE14: 98.427128 | DF14: 98.459156 | DG14: 98.575872 | DH14: 98.614099 | DI14: 98.620352 | DJ14: 98.702606 | DK14: 98.882008 | DL14: 98.705601 | DM14: 98.777387 | DN14: 98.730099 | DO14: 98.709738 | DP14: 98.963831 | DQ14: 98.879358 | DR14: 99.099301 | DS14: 99.107274 | DT14: 99.026565 | DU14: 99.160612 | DV14: 99.17527 | DW14: 99.169921 | DX14: 99.215426 | DY14: 99.281879 | DZ14: 99.299264 | EA14: 99.291739 | EB14: 99.291838 | EC14: 99.390467 | ED14: 99.335551 | EE14: 99.371509 | EF14: 99.391199 | EG14: 99.417621 | EH14: 99.504038 | EI14: 99.643245 | EJ14: 99.718915 | EK14: 100.10612 | EL14: 100.10418 | EM14: 100.49331 | EN14: 100.36236 | EO14: 100.39797 | EP14: 100.40127 | EQ14: 100.45976 | ER14: 100.31484 | ES14: 100.38917 | ET14: 100.39963 | EU14: 100.38218 | EV14: 100.40958 | EW14: 100.42959 | EX14: 100.34376 | EY14: 100.36056 | EZ14: 100.37518 | FA14: 100.38706 | FB14: 100.35199 | FC14: 100.33586 | FD14: 100.3 | FE14: 100.4 | FF14: 100.5 | FG14: 100.5 | FH14: 100.5 | FI14: 100.5 | FJ14: 100.46721 | FK14: 100.48206 | FL14: 100.46773 | FM14: 100.36743 | FN14: 100.18655 | FO14: 100.19361 | FP14: 100.2 | FQ14: 100.2 | FR14: 100.1 | FS14: 100.10131 | FT14: 100.06452 | FU14: 100.02774 | FV14: 99.990949 | FW14: 99.954162 | FX14: 99.917376 | FY14: 99.880589 | FZ14: 99.843803 | GA14: 99.807016 | GB14: 99.77023 | GC14: 99.733443 | GD14: 99.696657 | GE14: 99.65987 | GF14: 99.623084 | GG14: 99.586297 | GH14: 99.549511 | GI14: 99.512724 | GJ14: 99.475938 | GK14: 99.439151 | GL14: 99.402365 | GM14: 99.365578 | GN14: 99.328792 | GO14: 99.292005 | GP14: 99.255219 | GQ14: 99.218432 | GR14: 99.181646 | GS14: 99.144859 | GT14: 99.108073 | GU14: 99.071286 | GV14: 99.0345 | GW14: 98.997713 | GX14: 98.960927 | GY14: 98.92414 | GZ14: 98.887354 | HA14: 98.850567 | HB14: 98.813781 | HC14: 98.776994 | HD14: 98.740208
A15: 09 | B15: Loisirs et culture | C15: 3.35 | P15: 90.807201 | Q15: 90.516049 | R15: 90.238763 | S15: 90.122192 | T15: 90.5538 | U15: 90.344972 | V15: 90.752962 | W15: 90.530136 | X15: 90.869974 | Y15: 91.398812 | Z15: 91.339866 | AA15: 91.056057 | AB15: 91.145053 | AC15: 90.633791 | AD15: 90.661605 | AE15: 91.118032 | AF15: 90.891416 | AG15: 90.799659 | AH15: 90.62924 | AI15: 90.933267 | AJ15: 90.52511 | AK15: 90.90975 | AL15: 91.522687 | AM15: 91.346831 | AN15: 90.918562 | AO15: 91.024737 | AP15: 91.190564 | AQ15: 91.557165 | AR15: 91.734128 | AS15: 91.80215 | AT15: 91.726477 | AU15: 91.657254 | AV15: 91.874328 | AW15: 91.717403 | AX15: 91.7711 | AY15: 91.908704 | AZ15: 91.058927 | BA15: 91.161412 | BB15: 91.041131 | BC15: 91.01742 | BD15: 91.249093 | BE15: 91.413945 | BF15: 91.395953 | BG15: 91.806572 | BH15: 93.83197 | BI15: 93.149031 | BJ15: 93.209064 | BK15: 93.187644 | BL15: 93.025378 | BM15: 92.890153 | BN15: 92.970848 | BO15: 93.268497 | BP15: 93.296146 | BQ15: 93.076907 | BR15: 93.075114 | BS15: 93.141784 | BT15: 93.717944 | BU15: 93.781979 | BV15: 93.554264 | BW15: 93.806339 | BX15: 93.646841 | BY15: 93.860991 | BZ15: 93.320224 | CA15: 93.736621 | CB15: 93.887676 | CC15: 93.709155 | CD15: 93.773392 | CE15: 94.087804 | CF15: 94.12597 | CG15: 94.147722 | CH15: 94.204186 | CI15: 94.251005 | CJ15: 94.17162 | CK15: 94.220282 | CL15: 94.150784 | CM15: 94.333574 | CN15: 94.486335 | CO15: 94.819904 | CP15: 94.958205 | CQ15: 95.005144 | CR15: 95.047964 | CS15: 95.045653 | CT15: 94.96009 | CU15: 94.980287 | CV15: 94.944956 | CW15: 94.975013 | CX15: 95.327615 | CY15: 95.71712 | CZ15: 95.843754 | DA15: 96.010969 | DB15: 96.051893 | DC15: 96.203938 | DD15: 96.362523 | DE15: 96.493855 | DF15: 96.444111 | DG15: 96.49114 | DH15: 96.51941 | DI15: 96.510137 | DJ15: 96.510497 | DK15: 97.510462 | DL15: 97.545578 | DM15: 97.632 | DN15: 97.558533 | DO15: 97.547343 | DP15: 97.655588 | DQ15: 97.796841 | DR15: 97.993412 | DS15: 97.982773 | DT15: 98.005158 | DU15: 97.99887 | DV15: 98.008896 | DW15: 98.112625 | DX15: 97.989913 | DY15: 97.980815 | DZ15: 98.269853 | EA15: 98.466189 | EB15: 98.528848 | EC15: 98.591776 | ED15: 98.834409 | EE15: 99.192075 | EF15: 99.299927 | EG15: 99.340532 | EH15: 99.445039 | EI15: 99.751741 | EJ15: 99.91811 | EK15: 99.943636 | EL15: 100.2725 | EM15: 99.99689 | EN15: 100.22426 | EO15: 100.21172 | EP15: 100.60617 | EQ15: 100.98949 | ER15: 101.09553 | ES15: 101.20506 | ET15: 101.37786 | EU15: 101.44223 | EV15: 101.49392 | EW15: 101.50869 | EX15: 101.65856 | EY15: 102.30944 | EZ15: 102.63008 | FA15: 102.55037 | FB15: 102.55832 | FC15: 102.64248 | FD15: 102.6 | FE15: 102.6 | FF15: 102.6 | FG15: 102.6 | FH15: 102.6 | FI15: 102.4 | FJ15: 102.31131 | FK15: 102.97287 | FL15: 102.98387 | FM15: 102.96465 | FN15: 103.02843 | FO15: 103.0735 | FP15: 103 | FQ15: 103 | FR15: 103 | FS15: 103.17368 | FT15: 103.22559 | FU15: 103.27749 | FV15: 103.3294 | FW15: 103.3813 | FX15: 103.4332 | FY15: 103.48511 | FZ15: 103.53701 | GA15: 103.58892 | GB15: 103.64082 | GC15: 103.69272 | GD15: 103.74463 | GE15: 103.79653 | GF15: 103.84844 | GG15: 103.90034 | GH15: 103.95224 | GI15: 104.00415 | GJ15: 104.05605 | GK15: 104.10796 | GL15: 104.15986 | GM15: 104.21176 | GN15: 104.26367 | GO15: 104.31557 | GP15: 104.36747 | GQ15: 104.41938 | GR15: 104.47128 | GS15: 104.52319 | GT15: 104.57509 | GU15: 104.62699 | GV15: 104.6789 | GW15: 104.7308 | GX15: 104.78271 | GY15: 104.83461 | GZ15: 104.88651 | HA15: 104.93842 | HB15: 104.99032 | HC15: 105.04223 | HD15: 105.09413
A16: 10 | B16: Enseignement | C16: 3.07 | P16: 83.11472 | Q16: 83.096547 | R16: 83.140907 | S16: 83.161192 | T16: 83.37625 | U16: 83.340789 | V16: 83.659642 | W16: 85.967069 | X16: 86.689936 | Y16: 87.075012 | Z16: 87.132441 | AA16: 87.222076 | AB16: 87.063183 | AC16: 87.078945 | AD16: 87.093616 | AE16: 87.108097 | AF16: 87.059573 | AG16: 87.059666 | AH16: 86.900269 | AI16: 87.293366 | AJ16: 87.636771 | AK16: 87.75831 | AL16: 87.793007 | AM16: 87.749605 | AN16: 87.681546 | AO16: 87.611771 | AP16: 87.633121 | AQ16: 87.702643 | AR16: 87.716935 | AS16: 87.671107 | AT16: 87.882671 | AU16: 88.53612 | AV16: 88.955976 | AW16: 88.957126 | AX16: 89.266468 | AY16: 89.09792 | AZ16: 89.136161 | BA16: 89.192125 | BB16: 89.139123 | BC16: 89.077693 | BD16: 89.053481 | BE16: 89.297105 | BF16: 89.184412 | BG16: 90.324766 | BH16: 91.718299 | BI16: 92.072873 | BJ16: 91.998738 | BK16: 91.976042 | BL16: 91.952655 | BM16: 91.983641 | BN16: 92.256164 | BO16: 92.262496 | BP16: 92.219009 | BQ16: 92.397429 | BR16: 92.685051 | BS16: 92.794723 | BT16: 93.394919 | BU16: 92.689988 | BV16: 92.829019 | BW16: 92.901635 | BX16: 93.08683 | BY16: 92.983187 | BZ16: 93.003133 | CA16: 93.24414 | CB16: 93.21419 | CC16: 93.224122 | CD16: 93.237803 | CE16: 93.432766 | CF16: 93.996623 | CG16: 94.000738 | CH16: 93.99278 | CI16: 94.012177 | CJ16: 94.034266 | CK16: 94.146576 | CL16: 94.130672 | CM16: 94.154999 | CN16: 94.195043 | CO16: 94.193912 | CP16: 94.274421 | CQ16: 94.628951 | CR16: 95.15643 | CS16: 95.283747 | CT16: 95.484758 | CU16: 95.475344 | CV16: 95.514163 | CW16: 95.565986 | CX16: 95.531511 | CY16: 95.589257 | CZ16: 95.615077 | DA16: 95.613841 | DB16: 95.631576 | DC16: 95.86204 | DD16: 95.929074 | DE16: 96.02554 | DF16: 96.01067 | DG16: 96.273614 | DH16: 96.04585 | DI16: 96.103072 | DJ16: 96.103466 | DK16: 96.174123 | DL16: 96.174123 | DM16: 96.174489 | DN16: 96.304475 | DO16: 96.304294 | DP16: 96.552366 | DQ16: 96.75522 | DR16: 96.977705 | DS16: 96.97998 | DT16: 97.023121 | DU16: 97.023746 | DV16: 97.030586 | DW16: 97.031428 | DX16: 97.016813 | DY16: 97.030586 | DZ16: 97.422587 | EA16: 97.790411 | EB16: 97.900116 | EC16: 98.161318 | ED16: 98.478174 | EE16: 98.553192 | EF16: 98.556566 | EG16: 98.619934 | EH16: 98.640575 | EI16: 98.644528 | EJ16: 98.677845 | EK16: 98.676114 | EL16: 99.221228 | EM16: 101.00157 | EN16: 101.89516 | EO16: 102.00279 | EP16: 102.03101 | EQ16: 102.03267 | ER16: 102.22269 | ES16: 102.30111 | ET16: 102.30369 | EU16: 102.30364 | EV16: 102.28338 | EW16: 102.32529 | EX16: 102.55367 | EY16: 103.72552 | EZ16: 104.42944 | FA16: 104.46204 | FB16: 104.50061 | FC16: 104.50058 | FD16: 104.5 | FE16: 104.5 | FF16: 104.5 | FG16: 104.5 | FH16: 104.5 | FI16: 104.6 | FJ16: 105.10591 | FK16: 105.51086 | FL16: 105.94609 | FM16: 106.06876 | FN16: 106.08865 | FO16: 106.08528 | FP16: 106.1 | FQ16: 106.2 | FR16: 106.3 | FS16: 106.75732 | FT16: 106.93688 | FU16: 107.11643 | FV16: 107.29599 | FW16: 107.47554 | FX16: 107.6551 | FY16: 107.83466 | FZ16: 108.01421 | GA16: 108.19377 | GB16: 108.37332 | GC16: 108.55288 | GD16: 108.73244 | GE16: 108.91199 | GF16: 109.09155 | GG16: 109.2711 | GH16: 109.45066 | GI16: 109.63022 | GJ16: 109.80977 | GK16: 109.98933 | GL16: 110.16888 | GM16: 110.34844 | GN16: 110.528 | GO16: 110.70755 | GP16: 110.88711 | GQ16: 111.06667 | GR16: 111.24622 | GS16: 111.42578 | GT16: 111.60533 | GU16: 111.78489 | GV16: 111.96445 | GW16: 112.144 | GX16: 112.32356 | GY16: 112.50311 | GZ16: 112.68267 | HA16: 112.86223 | HB16: 113.04178 | HC16: 113.22134 | HD16: 113.40089
A17: 11 | B17: Restarants et hotels | C17: 6.69 | P17: 71.228498 | Q17: 71.454467 | R17: 71.918171 | S17: 71.993088 | T17: 72.435784 | U17: 72.254743 | V17: 72.150315 | W17: 72.515852 | X17: 72.079277 | Y17: 72.304682 | Z17: 72.763237 | AA17: 72.882939 | AB17: 72.4818 | AC17: 72.701156 | AD17: 73.027431 | AE17: 72.676854 | AF17: 72.992595 | AG17: 73.424021 | AH17: 73.509907 | AI17: 74.092527 | AJ17: 74.368594 | AK17: 74.197874 | AL17: 74.237579 | AM17: 74.651606 | AN17: 74.788313 | AO17: 74.756516 | AP17: 74.379348 | AQ17: 74.874693 | AR17: 75.692309 | AS17: 75.627953 | AT17: 76.566407 | AU17: 77.209864 | AV17: 77.322994 | AW17: 77.264918 | AX17: 77.296747 | AY17: 77.936391 | AZ17: 77.310871 | BA17: 78.633481 | BB17: 79.962448 | BC17: 80.570569 | BD17: 80.731512 | BE17: 80.909382 | BF17: 81.486844 | BG17: 81.396696 | BH17: 81.436264 | BI17: 81.369568 | BJ17: 81.606518 | BK17: 81.776946 | BL17: 82.860211 | BM17: 83.224383 | BN17: 82.881018 | BO17: 83.273307 | BP17: 83.234307 | BQ17: 83.450511 | BR17: 83.200629 | BS17: 83.588686 | BT17: 83.813404 | BU17: 83.609053 | BV17: 83.650685 | BW17: 83.78754 | BX17: 84.192102 | BY17: 84.215206 | BZ17: 84.12614 | CA17: 84.458441 | CB17: 84.002961 | CC17: 84.229853 | CD17: 84.22297 | CE17: 84.280294 | CF17: 83.97722 | CG17: 83.999816 | CH17: 84.052728 | CI17: 84.147782 | CJ17: 84.633024 | CK17: 84.607331 | CL17: 84.617697 | CM17: 84.484259 | CN17: 84.756252 | CO17: 85.207539 | CP17: 85.998021 | CQ17: 86.206637 | CR17: 86.273785 | CS17: 86.362596 | CT17: 86.617648 | CU17: 87.795649 | CV17: 88.26956 | CW17: 88.241194 | CX17: 89.941082 | CY17: 90.610147 | CZ17: 90.92528 | DA17: 90.949333 | DB17: 91.054837 | DC17: 91.094824 | DD17: 91.103758 | DE17: 91.301546 | DF17: 91.382196 | DG17: 91.612759 | DH17: 91.946766 | DI17: 92.004806 | DJ17: 92.173191 | DK17: 92.316225 | DL17: 92.330639 | DM17: 92.352728 | DN17: 92.84606 | DO17: 92.944149 | DP17: 92.912545 | DQ17: 93.142425 | DR17: 93.20072 | DS17: 93.268726 | DT17: 93.281945 | DU17: 93.333451 | DV17: 93.599744 | DW17: 93.756105 | DX17: 93.780884 | DY17: 93.828356 | DZ17: 93.900872 | EA17: 94.104987 | EB17: 94.105287 | EC17: 94.479001 | ED17: 94.594167 | EE17: 95.888905 | EF17: 96.495838 | EG17: 96.498986 | EH17: 96.858588 | EI17: 98.07712 | EJ17: 99.577539 | EK17: 99.992435 | EL17: 100.77612 | EM17: 101.10413 | EN17: 102.50189 | EO17: 102.40131 | EP17: 102.66359 | EQ17: 103.05245 | ER17: 103.40548 | ES17: 103.88592 | ET17: 104.34844 | EU17: 104.74065 | EV17: 104.83178 | EW17: 105.02078 | EX17: 105.04085 | EY17: 105.30507 | EZ17: 105.49083 | FA17: 105.66255 | FB17: 105.76815 | FC17: 105.90999 | FD17: 106 | FE17: 106.3 | FF17: 106.4 | FG17: 106.5 | FH17: 106.6 | FI17: 106.9 | FJ17: 107.04363 | FK17: 107.12739 | FL17: 107.22542 | FM17: 107.40225 | FN17: 107.80446 | FO17: 108.15033 | FP17: 108.4 | FQ17: 108.7 | FR17: 108.8 | FS17: 108.93287 | FT17: 109.14247 | FU17: 109.35207 | FV17: 109.56167 | FW17: 109.77127 | FX17: 109.98087 | FY17: 110.19048 | FZ17: 110.40008 | GA17: 110.60968 | GB17: 110.81928 | GC17: 111.02888 | GD17: 111.23849 | GE17: 111.44809 | GF17: 111.65769 | GG17: 111.86729 | GH17: 112.07689 | GI17: 112.28649 | GJ17: 112.4961 | GK17: 112.7057 | GL17: 112.9153 | GM17: 113.1249 | GN17: 113.3345 | GO17: 113.54411 | GP17: 113.75371 | GQ17: 113.96331 | GR17: 114.17291 | GS17: 114.38251 | GT17: 114.59211 | GU17: 114.80172 | GV17: 115.01132 | GW17: 115.22092 | GX17: 115.43052 | GY17: 115.64012 | GZ17: 115.84973 | HA17: 116.05933 | HB17: 116.26893 | HC17: 116.47853 | HD17: 116.68813
A18: 12 | B18: Biens et services divers | C18: 5.24 | P18: 81.880001 | Q18: 82.168669 | R18: 82.198026 | S18: 82.38611 | T18: 82.749387 | U18: 82.71451 | V18: 82.945127 | W18: 82.908824 | X18: 82.939116 | Y18: 83.28719 | Z18: 83.550226 | AA18: 83.427383 | AB18: 83.415814 | AC18: 83.716134 | AD18: 83.57797 | AE18: 83.620862 | AF18: 83.853336 | AG18: 84.087603 | AH18: 83.877718 | AI18: 84.280063 | AJ18: 84.133979 | AK18: 83.843134 | AL18: 84.032068 | AM18: 84.712627 | AN18: 83.943162 | AO18: 84.179739 | AP18: 84.306514 | AQ18: 84.499402 | AR18: 84.60762 | AS18: 84.397328 | AT18: 84.555895 | AU18: 84.747113 | AV18: 85.016939 | AW18: 84.862192 | AX18: 85.090431 | AY18: 86.186466 | AZ18: 86.266113 | BA18: 86.048707 | BB18: 86.160264 | BC18: 86.230977 | BD18: 86.735175 | BE18: 87.1392 | BF18: 86.876573 | BG18: 86.986491 | BH18: 87.255875 | BI18: 87.797965 | BJ18: 87.727646 | BK18: 88.248148 | BL18: 87.983665 | BM18: 87.732881 | BN18: 87.826821 | BO18: 88.156128 | BP18: 88.063567 | BQ18: 88.319983 | BR18: 88.633821 | BS18: 88.772165 | BT18: 88.879451 | BU18: 89.109877 | BV18: 89.078533 | BW18: 89.354371 | BX18: 89.397966 | BY18: 89.195131 | BZ18: 89.65775 | CA18: 89.868567 | CB18: 89.979357 | CC18: 89.980894 | CD18: 90.486219 | CE18: 90.467766 | CF18: 90.772064 | CG18: 90.730372 | CH18: 90.606087 | CI18: 90.714732 | CJ18: 90.735813 | CK18: 90.653657 | CL18: 90.739666 | CM18: 90.87477 | CN18: 91.312445 | CO18: 91.218955 | CP18: 91.505903 | CQ18: 91.871303 | CR18: 92.143848 | CS18: 92.230519 | CT18: 92.276647 | CU18: 92.581946 | CV18: 92.829977 | CW18: 92.940303 | CX18: 93.330738 | CY18: 93.520623 | CZ18: 93.753419 | DA18: 93.886091 | DB18: 94.113736 | DC18: 94.271288 | DD18: 94.252644 | DE18: 94.307416 | DF18: 94.364584 | DG18: 94.596392 | DH18: 94.47432 | DI18: 94.594891 | DJ18: 94.545792 | DK18: 94.8119 | DL18: 94.823287 | DM18: 94.924761 | DN18: 95.185227 | DO18: 95.286264 | DP18: 95.604567 | DQ18: 95.650759 | DR18: 95.664047 | DS18: 95.728216 | DT18: 95.75083 | DU18: 95.790209 | DV18: 95.898118 | DW18: 95.904906 | DX18: 95.949866 | DY18: 95.920815 | DZ18: 96.203465 | EA18: 96.266414 | EB18: 96.307372 | EC18: 96.423408 | ED18: 96.477706 | EE18: 96.698412 | EF18: 97.066258 | EG18: 97.402051 | EH18: 98.015727 | EI18: 98.617305 | EJ18: 99.225278 | EK18: 99.436523 | EL18: 100.36257 | EM18: 101.08484 | EN18: 101.49048 | EO18: 102.15007 | EP18: 102.3085 | EQ18: 102.8404 | ER18: 103.58785 | ES18: 104.18585 | ET18: 104.32907 | EU18: 104.81159 | EV18: 105.12352 | EW18: 105.38623 | EX18: 105.51816 | EY18: 105.60171 | EZ18: 105.97904 | FA18: 106.19745 | FB18: 106.2695 | FC18: 106.49664 | FD18: 106.6 | FE18: 107 | FF18: 107.2 | FG18: 107.4 | FH18: 107.4 | FI18: 107.7 | FJ18: 107.86559 | FK18: 107.98173 | FL18: 108.13308 | FM18: 108.31231 | FN18: 108.55529 | FO18: 108.65381 | FP18: 108.7 | FQ18: 108.9 | FR18: 108.9 | FS18: 109.1875 | FT18: 109.33844 | FU18: 109.48938 | FV18: 109.64033 | FW18: 109.79127 | FX18: 109.94221 | FY18: 110.09315 | FZ18: 110.24409 | GA18: 110.39504 | GB18: 110.54598 | GC18: 110.69692 | GD18: 110.84786 | GE18: 110.9988 | GF18: 111.14974 | GG18: 111.30069 | GH18: 111.45163 | GI18: 111.60257 | GJ18: 111.75351 | GK18: 111.90445 | GL18: 112.0554 | GM18: 112.20634 | GN18: 112.35728 | GO18: 112.50822 | GP18: 112.65916 | GQ18: 112.8101 | GR18: 112.96105 | GS18: 113.11199 | GT18: 113.26293 | GU18: 113.41387 | GV18: 113.56481 | GW18: 113.71575 | GX18: 113.8667 | GY18: 114.01764 | GZ18: 114.16858 | HA18: 114.31952 | HB18: 114.47046 | HC18: 114.62141 | HD18: 114.77235
B19: Indice général national | C19: Base 100 : Année 2022 | D19: =100*D42/$C$42 -> 99.204443 | E19: =100*E42/$C$42 -> 99.204443 | F19: =100*F42/$C$42 -> 98.844191 | G19: =100*G42/$C$42 -> 98.709096 | H19: =100*H42/$C$42 -> 99.11438 | I19: =100*I42/$C$42 -> 99.609727 | J19: =100*J42/$C$42 -> 100.06004 | K19: =100*K42/$C$42 -> 100.42029 | ... O19: =100*O42/$C$42 -> 101.59111 | P19: 79.02388 | Q19: 78.967071 | R19: 79.278134 | S19: 79.525025 | T19: 79.851858 | U19: 79.904067 | V19: 80.180041 | W19: 80.547843 | X19: 80.510138 | Y19: 80.85214 | Z19: 80.768846 | AA19: 81.452588 | AB19: 81.19512 | AC19: 81.077027 | AD19: 81.162108 | AE19: 81.153181 | AF19: 81.266962 | AG19: 81.458269 | AH19: 81.498899 | AI19: 81.841483 | AJ19: 82.082839 | AK19: 82.477123 | AL19: 82.556405 | AM19: 82.793213 | AN19: 82.275096 | AO19: 82.213218 | AP19: 82.08658 | AQ19: 81.909924 | AR19: 82.272009 | AS19: 82.100423 | AT19: 83.899547 | AU19: 83.998071 | AV19: 84.229622 | AW19: 84.147886 | AX19: 84.655882 | AY19: 84.962813 | AZ19: 84.397648 | BA19: 84.677755 | BB19: 84.687104 | BC19: 85.081483 | BD19: 85.252411 | BE19: 85.608482 | BF19: 85.855471 | BG19: 85.774064 | BH19: 86.037535 | BI19: 86.045874 | BJ19: 85.892604 | BK19: 86.19158 | BL19: 85.835242 | BM19: 85.780414 | BN19: 85.907061 | BO19: 86.018741 | BP19: 86.417576 | BQ19: 86.181658 | BR19: 86.24288 | BS19: 86.53152 | BT19: 86.515148 | BU19: 86.299978 | BV19: 86.279467 | BW19: 86.44287 | BX19: 86.201599 | BY19: 86.183208 | BZ19: 86.28667 | CA19: 86.68794 | CB19: 86.705851 | CC19: 86.683983 | CD19: 86.762931 | CE19: 87.084192 | CF19: 87.21904 | CG19: 87.10471 | CH19: 87.058789 | CI19: 87.101634 | CJ19: 86.954187 | CK19: 86.902572 | CL19: 86.937498 | CM19: 87.261293 | CN19: 87.464469 | CO19: 87.45869 | CP19: 87.56772 | CQ19: 87.700189 | CR19: 88.044006 | CS19: 88.474543 | CT19: 88.569602 | CU19: 88.820711 | CV19: 88.597979 | CW19: 88.843473 | CX19: 89.224982 | CY19: 89.518913 | CZ19: 89.560384 | DA19: 89.692628 | DB19: 89.929133 | DC19: 90.079647 | DD19: 90.211224 | DE19: 90.556304 | DF19: 90.808405 | DG19: 90.976811 | DH19: 91.042806 | DI19: 91.145462 | DJ19: 91.457468 | DK19: 91.916346 | DL19: 91.674918 | DM19: 91.796142 | DN19: 92.222614 | DO19: 92.380637 | DP19: 92.357382 | DQ19: 92.783228 | DR19: 92.734656 | DS19: 92.904901 | DT19: 92.763558 | DU19: 92.854903 | DV19: 93.183827 | DW19: 93.460136 | DX19: 93.718144 | DY19: 93.99004 | DZ19: 94.528441 | EA19: 94.490946 | EB19: 94.57814 | EC19: 94.791183 | ED19: 94.921906 | EE19: 96.116756 | EF19: 96.557472 | EG19: 96.979088 | EH19: 97.539374 | EI19: 98.655089 | EJ19: 99.276879 | EK19: 99.640201 | EL19: 100.33736 | EM19: 101.17588 | EN19: 101.81728 | EO19: 102.15679 | EP19: 102.71654 | EQ19: 103.14805 | ER19: 103.45322 | ES19: 104.95562 | ET19: 105.84497 | EU19: 106.55824 | EV19: 107.01192 | EW19: 107.65036 | EX19: 108.08785 | EY19: 108.67432 | EZ19: 108.87247 | FA19: 109.05942 | FB19: 109.06417 | FC19: 109.12723 | FD19: 108.8 | FE19: 110.2 | FF19: 110.9 | FG19: 111.5 | FH19: 111.8 | FI19: 112.2 | FJ19: 112.32466 | FK19: 112.79122 | FL19: 113.64635 | FM19: 113.9311 | FN19: 113.99542 | FO19: 114.70828 | FP19: 114.5 | FQ19: 114.6 | FR19: 115 | FS19: =SUMPRODUCT($C5:$C18,FS5:FS18)/100 -> 115.40704 | FT19: =SUMPRODUCT($C5:$C18,FT5:FT18)/100 -> 115.75438 | FU19: =SUMPRODUCT($C5:$C18,FU5:FU18)/100 -> 116.10172 | FV19: =SUMPRODUCT($C5:$C18,FV5:FV18)/100 -> 116.44906 | FW19: =SUMPRODUCT($C5:$C18,FW5:FW18)/100 -> 116.7964 | FX19: =SUMPRODUCT($C5:$C18,FX5:FX18)/100 -> 117.14374 | FY19: =SUMPRODUCT($C5:$C18,FY5:FY18)/100 -> 117.49108 | FZ19: =SUMPRODUCT($C5:$C18,FZ5:FZ18)/100 -> 117.83842 | ... II19: =SUMPRODUCT($C5:$C18,II5:II18)/100 -> 0
B21: Biens locaux | P21: 77.889298 | Q21: 77.752585 | R21: 78.036684 | S21: 78.416978 | T21: 78.800385 | U21: 78.739128 | V21: 79.294175 | W21: 79.858081 | X21: 79.901335 | Y21: 80.151294 | Z21: 80.103809 | AA21: 80.647366 | AB21: 80.464237 | AC21: 80.20582 | AD21: 80.187795 | AE21: 80.048009 | AF21: 80.230084 | AG21: 80.456226 | AH21: 80.566371 | AI21: 81.015328 | AJ21: 81.304754 | AK21: 81.762891 | AL21: 81.785735 | AM21: 81.837328 | AN21: 81.391288 | AO21: 81.339451 | AP21: 81.187215 | AQ21: 80.91203 | AR21: 81.373597 | AS21: 81.139098 | AT21: 83.075764 | AU21: 83.316269 | AV21: 83.620454 | AW21: 83.657625 | AX21: 84.188202 | AY21: 84.579983 | AZ21: 83.793598 | BA21: 84.10056 | BB21: 84.073775 | BC21: 84.498437 | BD21: 84.77679 | BE21: 85.164736 | BF21: 85.675226 | BG21: 85.554257 | BH21: 86.082914 | BI21: 86.110136 | BJ21: 85.939246 | BK21: 86.260315 | BL21: 85.808017 | BM21: 85.744234 | BN21: 85.763689 | BO21: 85.942993 | BP21: 86.656847 | BQ21: 86.285987 | BR21: 86.278909 | BS21: 86.820939 | BT21: 86.701115 | BU21: 86.5281 | BV21: 86.287602 | BW21: 86.414184 | BX21: 86.184432 | BY21: 86.235615 | BZ21: 86.377289 | CA21: 86.726659 | CB21: 86.6696 | CC21: 86.635225 | CD21: 86.722505 | CE21: 87.219884 | CF21: 87.490693 | CG21: 87.149243 | CH21: 87.003865 | CI21: 86.949875 | CJ21: 86.704819 | CK21: 86.643131 | CL21: 86.648485 | CM21: 86.848834 | CN21: 86.940755 | CO21: 86.883453 | CP21: 87.124629 | CQ21: 87.331719 | CR21: 87.811931 | CS21: 88.435017 | CT21: 88.393256 | CU21: 88.654632 | CV21: 88.385887 | CW21: 88.604908 | CX21: 88.965247 | CY21: 89.300759 | CZ21: 89.233063 | DA21: 89.274716 | DB21: 89.658984 | DC21: 89.842124 | DD21: 89.999872 | DE21: 90.387936 | DF21: 90.716532 | DG21: 90.864271 | DH21: 90.902287 | DI21: 91.061449 | DJ21: 91.464799 | DK21: 91.950745 | DL21: 91.528586 | DM21: 91.53953 | DN21: 92.127823 | DO21: 92.343029 | DP21: 92.313444 | DQ21: 92.8104 | DR21: 92.696015 | DS21: 92.865463 | DT21: 92.688447 | DU21: 92.764266 | DV21: 93.050718 | DW21: 93.400044 | DX21: 93.697892 | DY21: 93.970381 | DZ21: 94.651869 | EA21: 94.515212 | EB21: 94.572425 | EC21: 94.529128 | ED21: 94.519833 | EE21: 95.89753 | EF21: 96.416192 | EG21: 96.766365 | EH21: 97.342175 | EI21: 98.538549 | EJ21: 99.131431 | EK21: 99.451638 | EL21: 100.45611 | EM21: 101.28476 | EN21: 101.99009 | EO21: 102.30357 | EP21: 102.9917 | EQ21: 103.32741 | ER21: 103.9 | ES21: 105.4 | ET21: 106.5 | EU21: 107.3 | EV21: 107.8 | EW21: 108.5 | EX21: 108.9 | EY21: 109.6 | EZ21: 109.8 | FA21: 110 | FB21: 110 | FC21: 110.1 | FD21: 109.5 | FE21: 110.9 | FF21: 111.6 | FG21: 112.3 | FH21: 112.7 | FI21: 113.3 | FJ21: 113.3 | FK21: 113.9 | FL21: 114.7 | FM21: 115 | FN21: 115 | FO21: 115.9 | FP21: 115.6 | FQ21: 115.8 | FR21: 116.2
B22: Biens importés | P22: 82.675593 | Q22: 82.938721 | R22: 83.347076 | S22: 83.36653 | T22: 83.502698 | U22: 83.653523 | V22: 83.492754 | W22: 83.599757 | X22: 83.470678 | Y22: 83.531224 | Z22: 83.326144 | AA22: 84.738134 | AB22: 84.568791 | AC22: 84.709369 | AD22: 84.79651 | AE22: 85.022391 | AF22: 84.942453 | AG22: 84.799869 | AH22: 84.844856 | AI22: 84.880457 | AJ22: 84.981224 | AK22: 85.204252 | AL22: 85.134711 | AM22: 85.600363 | AN22: 85.450014 | AO22: 85.525703 | AP22: 85.374259 | AQ22: 85.402125 | AR22: 85.573689 | AS22: 85.599865 | AT22: 86.758555 | AU22: 86.70789 | AV22: 86.610645 | AW22: 86.312861 | AX22: 86.530821 | AY22: 86.733324 | AZ22: 86.445746 | BA22: 86.591507 | BB22: 86.549929 | BC22: 86.734469 | BD22: 86.96084 | BE22: 87.036579 | BF22: 86.724311 | BG22: 86.823628 | BH22: 86.755858 | BI22: 86.803873 | BJ22: 86.989726 | BK22: 86.867017 | BL22: 86.438505 | BM22: 86.354186 | BN22: 86.552482 | BO22: 86.207066 | BP22: 86.270881 | BQ22: 86.288607 | BR22: 86.391428 | BS22: 86.007372 | BT22: 85.933095 | BU22: 85.987468 | BV22: 86.0228 | BW22: 86.594965 | BX22: 86.158187 | BY22: 86.204363 | BZ22: 86.053541 | CA22: 86.364632 | CB22: 86.353395 | CC22: 86.531533 | CD22: 86.621804 | CE22: 86.943959 | CF22: 86.839486 | CG22: 87.114469 | CH22: 86.95817 | CI22: 87.232569 | CJ22: 87.406283 | CK22: 87.370889 | CL22: 87.495297 | CM22: 87.878426 | CN22: 88.238547 | CO22: 88.328256 | CP22: 88.506259 | CQ22: 88.645273 | CR22: 88.924012 | CS22: 88.982304 | CT22: 89.126542 | CU22: 89.315936 | CV22: 89.462907 | CW22: 89.614672 | CX22: 90.098877 | CY22: 90.210431 | CZ22: 90.258234 | DA22: 90.31024 | DB22: 90.146284 | DC22: 90.295891 | DD22: 90.37514 | DE22: 90.664671 | DF22: 90.815143 | DG22: 91.083201 | DH22: 91.070585 | DI22: 91.212598 | DJ22: 91.405903 | DK22: 92.115687 | DL22: 92.160773 | DM22: 92.597958 | DN22: 92.465324 | DO22: 92.640699 | DP22: 92.904298 | DQ22: 93.236763 | DR22: 93.370283 | DS22: 93.727756 | DT22: 93.995024 | DU22: 94.170615 | DV22: 94.785765 | DW22: 94.96086 | DX22: 94.964913 | DY22: 95.112223 | DZ22: 95.312265 | EA22: 95.33626 | EB22: 95.477516 | EC22: 95.595663 | ED22: 96.160655 | EE22: 96.788694 | EF22: 96.994877 | EG22: 97.62964 | EH22: 98.15626 | EI22: 99.021636 | EJ22: 99.733317 | EK22: 100.22402 | EL22: 99.964722 | EM22: 100.82567 | EN22: 101.28036 | EO22: 101.70027 | EP22: 101.87209 | EQ22: 102.59714 | ER22: 102.6 | ES22: 104.2 | ET22: 104.5 | EU22: 105.1 | EV22: 105.5 | EW22: 106 | EX22: 106.1 | EY22: 106.3 | EZ22: 106.5 | FA22: 106.6 | FB22: 106.7 | FC22: 106.9 | FD22: 106.9 | FE22: 108.4 | FF22: 108.8 | FG22: 109.4 | FH22: 109.6 | FI22: 109.6 | FJ22: 109.9 | FK22: 110 | FL22: 110.9 | FM22: 111.1 | FN22: 111.4 | FO22: 111.7 | FP22: 111.6 | FQ22: 111.7 | FR22: 111.8
